Workbook

Sheet Region 1
A1: APARTMENT CORP | RENT & VOUCHER DATA COLLECTION
A2: Region 1 | Regional Manager: JR Rolon | jrrolon@apartmentcorp.com
A3: SECTION 1 — CURRENT RENTS (monthly rent per unit type + AMI levels, HAP & CoStar)
A4: Property Name | B4: Studio | C4: 1 BR | D4: 2 BR | E4: 3 BR | F4: 4 BR | G4: 5 BR | H4: 30% AMI | I4: 35% AMI | J4: 40% AMI | K4: 50% AMI | L4: 55% AMI | M4: 60% AMI | N4: HAP | O4: CoStar | P4: Notes
A5: Boca Ciega Townhomes Apts
A6: Coral Village
A7: Cumberland Apts
A8: Holiday Apts
A9: Jefferson Arms Apts
A10: Macedonia Garden Apts
A11: Opa Locka - 135th St Apts
A12: Village Green Apts
A13: Walnut Hill Apartments
A15: SECTION 2 — VOUCHER PAYMENT STANDARDS (HAP / voucher amount per bedroom size)
A16: Property Name | B16: Studio | C16: 1 BR | D16: 2 BR | E16: 3 BR | F16: 4 BR | G16: 5 BR | H16: Notes
A17: Boca Ciega Townhomes Apts
A18: Coral Village
A19: Cumberland Apts
A20: Holiday Apts
A21: Jefferson Arms Apts
A22: Macedonia Garden Apts
A23: Opa Locka - 135th St Apts
A24: Village Green Apts
A25: Walnut Hill Apartments
A27: SECTION 3 — UTILITY ALLOWANCES (monthly utility allowance per bedroom size)
A28: Property Name | B28: Studio | C28: 1 BR | D28: 2 BR | E28: 3 BR | F28: 4 BR | G28: 5 BR | H28: Notes
A29: Boca Ciega Townhomes Apts
A30: Coral Village
A31: Cumberland Apts
A32: Holiday Apts
A33: Jefferson Arms Apts
A34: Macedonia Garden Apts
A35: Opa Locka - 135th St Apts
A36: Village Green Apts
A37: Walnut Hill Apartments

Sheet Region 2
A1: APARTMENT CORP | RENT & VOUCHER DATA COLLECTION
A2: Region 2 | Regional Manager: Susan Lopez | susan@apartmentcorp.com
A3: SECTION 1 — CURRENT RENTS (monthly rent per unit type + AMI levels, HAP & CoStar)
A4: Property Name | B4: Studio | C4: 1 BR | D4: 2 BR | E4: 3 BR | F4: 4 BR | G4: 5 BR | H4: 30% AMI | I4: 35% AMI | J4: 40% AMI | K4: 50% AMI | L4: 55% AMI | M4: 60% AMI | N4: HAP | O4: CoStar | P4: Notes
A5: Breckenridge Village
A6: Grace Townhomes
A7: Grove Park Terrace
A8: La Promesa
A9: Lexington Arms
A10: River Pointe Apts
A12: SECTION 2 — VOUCHER PAYMENT STANDARDS (HAP / voucher amount per bedroom size)
A13: Property Name | B13: Studio | C13: 1 BR | D13: 2 BR | E13: 3 BR | F13: 4 BR | G13: 5 BR | H13: Notes
A14: Breckenridge Village
A15: Grace Townhomes
A16: Grove Park Terrace
A17: La Promesa
A18: Lexington Arms
A19: River Pointe Apts
A21: SECTION 3 — UTILITY ALLOWANCES (monthly utility allowance per bedroom size)
A22: Property Name | B22: Studio | C22: 1 BR | D22: 2 BR | E22: 3 BR | F22: 4 BR | G22: 5 BR | H22: Notes
A23: Breckenridge Village
A24: Grace Townhomes
A25: Grove Park Terrace
A26: La Promesa
A27: Lexington Arms
A28: River Pointe Apts

Sheet Region 3
A1: APARTMENT CORP | RENT & VOUCHER DATA COLLECTION
A2: Region 3 | Regional Manager: Ginger Positerry | ginger@apartmentcorp.com
A3: SECTION 1 — CURRENT RENTS (monthly rent per unit type + AMI levels, HAP & CoStar)
A4: Property Name | B4: Studio | C4: 1 BR | D4: 2 BR | E4: 3 BR | F4: 4 BR | G4: 5 BR | H4: 30% AMI | I4: 35% AMI | J4: 40% AMI | K4: 50% AMI | L4: 55% AMI | M4: 60% AMI | N4: HAP | O4: CoStar | P4: Notes
A5: Arbor Crest Apts
A6: Bayou Pointe
A7: Gates - Property Manager
A8: Howell Place
A9: Marrero 3
A10: North Pointe
A11: Pelican Bay
A12: Pirates Bend
A13: Ruby Diamond / Star Homes
A14: St. Charles Place
A15: Thibodaux - Colonial Estates Apts
A16: Yorkshire (office)/Windsor Village
A18: SECTION 2 — VOUCHER PAYMENT STANDARDS (HAP / voucher amount per bedroom size)
A19: Property Name | B19: Studio | C19: 1 BR | D19: 2 BR | E19: 3 BR | F19: 4 BR | G19: 5 BR | H19: Notes
A20: Arbor Crest Apts
A21: Bayou Pointe
A22: Gates - Property Manager
A23: Howell Place
A24: Marrero 3
A25: North Pointe
A26: Pelican Bay
A27: Pirates Bend
A28: Ruby Diamond / Star Homes
A29: St. Charles Place
A30: Thibodaux - Colonial Estates Apts
A31: Yorkshire (office)/Windsor Village
A33: SECTION 3 — UTILITY ALLOWANCES (monthly utility allowance per bedroom size)
A34: Property Name | B34: Studio | C34: 1 BR | D34: 2 BR | E34: 3 BR | F34: 4 BR | G34: 5 BR | H34: Notes
A35: Arbor Crest Apts
A36: Bayou Pointe
A37: Gates - Property Manager
A38: Howell Place
A39: Marrero 3
A40: North Pointe
A41: Pelican Bay
A42: Pirates Bend
...

Sheet Region 4
A1: APARTMENT CORP | RENT & VOUCHER DATA COLLECTION
A2: Region 4 | Regional Manager: Blake Weddington | blake@apartmentcorp.com
A3: SECTION 1 — CURRENT RENTS (monthly rent per unit type + AMI levels, HAP & CoStar)
A4: Property Name | B4: Studio | C4: 1 BR | D4: 2 BR | E4: 3 BR | F4: 4 BR | G4: 5 BR | H4: 30% AMI | I4: 35% AMI | J4: 40% AMI | K4: 50% AMI | L4: 55% AMI | M4: 60% AMI | N4: HAP | O4: CoStar | P4: Notes
A5: Anaheim Gardens Apts
A6: Columbia Village (Office)
A7: Fairfax Senior Apts (rings NWA)
A8: Forest View Senior Apts
A9: Granite Ridge Apts
A10: Midtown Manor (rings NWA)
A11: New Wilmington Arms (office)
A12: Oak Hills Apts
A13: Pacific Pointe Apts
A14: River Garden
A15: Urban Rehab 1 (rings NWA)
A16: Urban Rehab 2
A18: SECTION 2 — VOUCHER PAYMENT STANDARDS (HAP / voucher amount per bedroom size)
A19: Property Name | B19: Studio | C19: 1 BR | D19: 2 BR | E19: 3 BR | F19: 4 BR | G19: 5 BR | H19: Notes
A20: Anaheim Gardens Apts
A21: Columbia Village (Office)
A22: Fairfax Senior Apts (rings NWA)
A23: Forest View Senior Apts
A24: Granite Ridge Apts
A25: Midtown Manor (rings NWA)
A26: New Wilmington Arms (office)
A27: Oak Hills Apts
A28: Pacific Pointe Apts
A29: River Garden
A30: Urban Rehab 1 (rings NWA)
A31: Urban Rehab 2
A33: SECTION 3 — UTILITY ALLOWANCES (monthly utility allowance per bedroom size)
A34: Property Name | B34: Studio | C34: 1 BR | D34: 2 BR | E34: 3 BR | F34: 4 BR | G34: 5 BR | H34: Notes
A35: Anaheim Gardens Apts
A36: Columbia Village (Office)
A37: Fairfax Senior Apts (rings NWA)
A38: Forest View Senior Apts
A39: Granite Ridge Apts
A40: Midtown Manor (rings NWA)
A41: New Wilmington Arms (office)
A42: Oak Hills Apts
...

Sheet Region 5
A1: APARTMENT CORP | RENT & VOUCHER DATA COLLECTION
A2: Region 5 | Regional Manager: Leslie Rolon | leslie@apartmentcorp.com
A3: SECTION 1 — CURRENT RENTS (monthly rent per unit type + AMI levels, HAP & CoStar)
A4: Property Name | B4: Studio | C4: 1 BR | D4: 2 BR | E4: 3 BR | F4: 4 BR | G4: 5 BR | H4: 30% AMI | I4: 35% AMI | J4: 40% AMI | K4: 50% AMI | L4: 55% AMI | M4: 60% AMI | N4: HAP | O4: CoStar | P4: Notes
A5: Silver Springs Terrace Apts
A6: Thomasville Church Homes
A8: SECTION 2 — VOUCHER PAYMENT STANDARDS (HAP / voucher amount per bedroom size)
A9: Property Name | B9: Studio | C9: 1 BR | D9: 2 BR | E9: 3 BR | F9: 4 BR | G9: 5 BR | H9: Notes
A10: Silver Springs Terrace Apts
A11: Thomasville Church Homes
A13: SECTION 3 — UTILITY ALLOWANCES (monthly utility allowance per bedroom size)
A14: Property Name | B14: Studio | C14: 1 BR | D14: 2 BR | E14: 3 BR | F14: 4 BR | G14: 5 BR | H14: Notes
A15: Silver Springs Terrace Apts
A16: Thomasville Church Homes

Sheet CONSOLIDATED MASTER
A1: APARTMENT CORP | CONSOLIDATED RENT & VOUCHER DATA — ALL REGIONS
A2: This sheet auto-updates from each region's tab. Do not edit directly.
A3: Region 1 | JR Rolon — CURRENT RENTS (monthly rent per unit type + AMI levels, HAP & CoStar)
A4: Property Name | B4: Studio | C4: 1 BR | D4: 2 BR | E4: 3 BR | F4: 4 BR | G4: 5 BR | H4: 30% AMI | I4: 35% AMI | J4: 40% AMI | K4: 50% AMI | L4: 55% AMI | M4: 60% AMI | N4: HAP | O4: CoStar | P4: Notes
A5: ='Region 1'!A5 | B5: ='Region 1'!B5 | C5: ='Region 1'!C5 | D5: ='Region 1'!D5 | E5: ='Region 1'!E5 | F5: ='Region 1'!F5 | G5: ='Region 1'!G5 | H5: ='Region 1'!H5 | ... P5: ='Region 1'!P5
A6: ='Region 1'!A6 | B6: ='Region 1'!B6 | C6: ='Region 1'!C6 | D6: ='Region 1'!D6 | E6: ='Region 1'!E6 | F6: ='Region 1'!F6 | G6: ='Region 1'!G6 | H6: ='Region 1'!H6 | ... P6: ='Region 1'!P6
A7: ='Region 1'!A7 | B7: ='Region 1'!B7 | C7: ='Region 1'!C7 | D7: ='Region 1'!D7 | E7: ='Region 1'!E7 | F7: ='Region 1'!F7 | G7: ='Region 1'!G7 | H7: ='Region 1'!H7 | ... P7: ='Region 1'!P7
A8: ='Region 1'!A8 | B8: ='Region 1'!B8 | C8: ='Region 1'!C8 | D8: ='Region 1'!D8 | E8: ='Region 1'!E8 | F8: ='Region 1'!F8 | G8: ='Region 1'!G8 | H8: ='Region 1'!H8 | ... P8: ='Region 1'!P8
A9: ='Region 1'!A9 | B9: ='Region 1'!B9 | C9: ='Region 1'!C9 | D9: ='Region 1'!D9 | E9: ='Region 1'!E9 | F9: ='Region 1'!F9 | G9: ='Region 1'!G9 | H9: ='Region 1'!H9 | ... P9: ='Region 1'!P9
A10: ='Region 1'!A10 | B10: ='Region 1'!B10 | C10: ='Region 1'!C10 | D10: ='Region 1'!D10 | E10: ='Region 1'!E10 | F10: ='Region 1'!F10 | G10: ='Region 1'!G10 | H10: ='Region 1'!H10 | ... P10: ='Region 1'!P10
A11: ='Region 1'!A11 | B11: ='Region 1'!B11 | C11: ='Region 1'!C11 | D11: ='Region 1'!D11 | E11: ='Region 1'!E11 | F11: ='Region 1'!F11 | G11: ='Region 1'!G11 | H11: ='Region 1'!H11 | ... P11: ='Region 1'!P11
A12: ='Region 1'!A12 | B12: ='Region 1'!B12 | C12: ='Region 1'!C12 | D12: ='Region 1'!D12 | E12: ='Region 1'!E12 | F12: ='Region 1'!F12 | G12: ='Region 1'!G12 | H12: ='Region 1'!H12 | ... P12: ='Region 1'!P12
A13: ='Region 1'!A13 | B13: ='Region 1'!B13 | C13: ='Region 1'!C13 | D13: ='Region 1'!D13 | E13: ='Region 1'!E13 | F13: ='Region 1'!F13 | G13: ='Region 1'!G13 | H13: ='Region 1'!H13 | ... P13: ='Region 1'!P13
A15: Region 1 | JR Rolon — VOUCHER PAYMENT STANDARDS (HAP / voucher amount per bedroom size)
A16: Property Name | B16: Studio | C16: 1 BR | D16: 2 BR | E16: 3 BR | F16: 4 BR | G16: 5 BR | H16: Notes
A17: ='Region 1'!A17 | B17: ='Region 1'!B17 | C17: ='Region 1'!C17 | D17: ='Region 1'!D17 | E17: ='Region 1'!E17 | F17: ='Region 1'!F17 | G17: ='Region 1'!G17 | H17: ='Region 1'!H17
A18: ='Region 1'!A18 | B18: ='Region 1'!B18 | C18: ='Region 1'!C18 | D18: ='Region 1'!D18 | E18: ='Region 1'!E18 | F18: ='Region 1'!F18 | G18: ='Region 1'!G18 | H18: ='Region 1'!H18
A19: ='Region 1'!A19 | B19: ='Region 1'!B19 | C19: ='Region 1'!C19 | D19: ='Region 1'!D19 | E19: ='Region 1'!E19 | F19: ='Region 1'!F19 | G19: ='Region 1'!G19 | H19: ='Region 1'!H19
A20: ='Region 1'!A20 | B20: ='Region 1'!B20 | C20: ='Region 1'!C20 | D20: ='Region 1'!D20 | E20: ='Region 1'!E20 | F20: ='Region 1'!F20 | G20: ='Region 1'!G20 | H20: ='Region 1'!H20
A21: ='Region 1'!A21 | B21: ='Region 1'!B21 | C21: ='Region 1'!C21 | D21: ='Region 1'!D21 | E21: ='Region 1'!E21 | F21: ='Region 1'!F21 | G21: ='Region 1'!G21 | H21: ='Region 1'!H21
A22: ='Region 1'!A22 | B22: ='Region 1'!B22 | C22: ='Region 1'!C22 | D22: ='Region 1'!D22 | E22: ='Region 1'!E22 | F22: ='Region 1'!F22 | G22: ='Region 1'!G22 | H22: ='Region 1'!H22
A23: ='Region 1'!A23 | B23: ='Region 1'!B23 | C23: ='Region 1'!C23 | D23: ='Region 1'!D23 | E23: ='Region 1'!E23 | F23: ='Region 1'!F23 | G23: ='Region 1'!G23 | H23: ='Region 1'!H23
A24: ='Region 1'!A24 | B24: ='Region 1'!B24 | C24: ='Region 1'!C24 | D24: ='Region 1'!D24 | E24: ='Region 1'!E24 | F24: ='Region 1'!F24 | G24: ='Region 1'!G24 | H24: ='Region 1'!H24
A25: ='Region 1'!A25 | B25: ='Region 1'!B25 | C25: ='Region 1'!C25 | D25: ='Region 1'!D25 | E25: ='Region 1'!E25 | F25: ='Region 1'!F25 | G25: ='Region 1'!G25 | H25: ='Region 1'!H25
A27: Region 1 | JR Rolon — UTILITY ALLOWANCES (monthly utility allowance per bedroom size)
A28: Property Name | B28: Studio | C28: 1 BR | D28: 2 BR | E28: 3 BR | F28: 4 BR | G28: 5 BR | H28: Notes
A29: ='Region 1'!A29 | B29: ='Region 1'!B29 | C29: ='Region 1'!C29 | D29: ='Region 1'!D29 | E29: ='Region 1'!E29 | F29: ='Region 1'!F29 | G29: ='Region 1'!G29 | H29: ='Region 1'!H29
A30: ='Region 1'!A30 | B30: ='Region 1'!B30 | C30: ='Region 1'!C30 | D30: ='Region 1'!D30 | E30: ='Region 1'!E30 | F30: ='Region 1'!F30 | G30: ='Region 1'!G30 | H30: ='Region 1'!H30
A31: ='Region 1'!A31 | B31: ='Region 1'!B31 | C31: ='Region 1'!C31 | D31: ='Region 1'!D31 | E31: ='Region 1'!E31 | F31: ='Region 1'!F31 | G31: ='Region 1'!G31 | H31: ='Region 1'!H31
A32: ='Region 1'!A32 | B32: ='Region 1'!B32 | C32: ='Region 1'!C32 | D32: ='Region 1'!D32 | E32: ='Region 1'!E32 | F32: ='Region 1'!F32 | G32: ='Region 1'!G32 | H32: ='Region 1'!H32
A33: ='Region 1'!A33 | B33: ='Region 1'!B33 | C33: ='Region 1'!C33 | D33: ='Region 1'!D33 | E33: ='Region 1'!E33 | F33: ='Region 1'!F33 | G33: ='Region 1'!G33 | H33: ='Region 1'!H33
A34: ='Region 1'!A34 | B34: ='Region 1'!B34 | C34: ='Region 1'!C34 | D34: ='Region 1'!D34 | E34: ='Region 1'!E34 | F34: ='Region 1'!F34 | G34: ='Region 1'!G34 | H34: ='Region 1'!H34
A35: ='Region 1'!A35 | B35: ='Region 1'!B35 | C35: ='Region 1'!C35 | D35: ='Region 1'!D35 | E35: ='Region 1'!E35 | F35: ='Region 1'!F35 | G35: ='Region 1'!G35 | H35: ='Region 1'!H35
A36: ='Region 1'!A36 | B36: ='Region 1'!B36 | C36: ='Region 1'!C36 | D36: ='Region 1'!D36 | E36: ='Region 1'!E36 | F36: ='Region 1'!F36 | G36: ='Region 1'!G36 | H36: ='Region 1'!H36
A37: ='Region 1'!A37 | B37: ='Region 1'!B37 | C37: ='Region 1'!C37 | D37: ='Region 1'!D37 | E37: ='Region 1'!E37 | F37: ='Region 1'!F37 | G37: ='Region 1'!G37 | H37: ='Region 1'!H37
A39: Region 2 | Susan Lopez — CURRENT RENTS (monthly rent per unit type + AMI levels, HAP & CoStar)
A40: Property Name | B40: Studio | C40: 1 BR | D40: 2 BR | E40: 3 BR | F40: 4 BR | G40: 5 BR | H40: 30% AMI | I40: 35% AMI | J40: 40% AMI | K40: 50% AMI | L40: 55% AMI | M40: 60% AMI | N40: HAP | O40: CoStar | P40: Notes
A41: ='Region 2'!A5 | B41: ='Region 2'!B5 | C41: ='Region 2'!C5 | D41: ='Region 2'!D5 | E41: ='Region 2'!E5 | F41: ='Region 2'!F5 | G41: ='Region 2'!G5 | H41: ='Region 2'!H5 | ... P41: ='Region 2'!P5
A42: ='Region 2'!A6 | B42: ='Region 2'!B6 | C42: ='Region 2'!C6 | D42: ='Region 2'!D6 | E42: ='Region 2'!E6 | F42: ='Region 2'!F6 | G42: ='Region 2'!G6 | H42: ='Region 2'!H6 | ... P42: ='Region 2'!P6
A43: ='Region 2'!A7 | B43: ='Region 2'!B7 | C43: ='Region 2'!C7 | D43: ='Region 2'!D7 | E43: ='Region 2'!E7 | F43: ='Region 2'!F7 | G43: ='Region 2'!G7 | H43: ='Region 2'!H7 | ... P43: ='Region 2'!P7
...

Sheet Region Summary
A1: APARTMENT CORP | REGION SUMMARY
A2: Region | B2: Regional Manager | C2: Email | D2: # Properties | E2: Properties
A3: Region 1 | B3: JR Rolon | C3: jrrolon@apartmentcorp.com | D3: 9 | E3: Boca Ciega Townhomes Apts, Coral Village, Cumberland Apts, Holiday Apts, Jefferson Arms Apts, Macedonia Garden Apts, Opa Locka - 135th St Apts, Village Green Apts, Walnut Hill Apartments
A4: Region 2 | B4: Susan Lopez | C4: susan@apartmentcorp.com | D4: 6 | E4: Breckenridge Village, Grace Townhomes, Grove Park Terrace, La Promesa, Lexington Arms, River Pointe Apts
A5: Region 3 | B5: Ginger Positerry | C5: ginger@apartmentcorp.com | D5: 12 | E5: Arbor Crest Apts, Bayou Pointe, Gates - Property Manager, Howell Place, Marrero 3, North Pointe, Pelican Bay, Pirates Bend, Ruby Diamond / Star Homes, St. Charles Place, Thibodaux - Colonial Estates Apts, Yorkshire (office)/Windsor Village
A6: Region 4 | B6: Blake Weddington | C6: blake@apartmentcorp.com | D6: 12 | E6: Anaheim Gardens Apts, Columbia Village (Office), Fairfax Senior Apts (rings NWA), Forest View Senior Apts, Granite Ridge Apts, Midtown Manor (rings NWA), New Wilmington Arms (office), Oak Hills Apts, Pacific Pointe Apts, River Garden, Urban Rehab 1 (rings NWA), Urban Rehab 2
A7: Region 5 | B7: Leslie Rolon | C7: leslie@apartmentcorp.com | D7: 2 | E7: Silver Springs Terrace Apts, Thomasville Church Homes
