Workbook

Sheet INDEX
A7: APARTMENT CORP — COMPETITIVE RENT COMP ANALYSIS 2026
A8: LEGEND for Each sheet: 3 GREEN rows = Affordable/Low-Income comps (LIHTC/Section 8/HUD) | 6 BLUE rows = Market Rate comps (no income restrictions) Rents: Low (50% AMI) | Mid (60% AMI LIHTC ceiling) | FMR (HUD Fair Market Rent) | Actual (verified advertised rent)
A9: # | B9: Property Name | C9: City, State | D9: Year Built | E9: Units | F9: Program | G9: Sheet Name | H9: Bedroom Mix | I9: Comp Types
A10: 1 | B10: Boca Ciega | C10: St. Petersburg, FL | D10: 1974 | E10: 109 | F10: Layered HUD/LIHTC | G10: 21 - Boca Ciega | H10: 2BR / 3BR | I10: 3 Affordable (Green) + 6 Market Rate (Blue)
A11: 2 | B11: Jefferson Arms | C11: Monticello, FL | D11: 1971 | E11: 75 | F11: Section 8/HUD | G11: 13 - Jefferson | H11: 2BR / 3BR | I11: 3 Affordable (Green) + 6 Market Rate (Blue)
A12: 3 | B12: Opa Locka 135th St | C12: Opa Locka, FL | D12: 1968 | E12: 65 | F12: Section 8/HUD | G12: 18 - Opa Locka | H12: 1BR / 2BR / 3BR | I12: 3 Affordable (Green) + 6 Market Rate (Blue)
A13: 4 | B13: Macedonia Garden | C13: Panama City, FL | D13: 1969 | E13: 100 | F13: Section 8/HUD | G13: 14 - Macedonia | H13: 2BR / 3BR | I13: 3 Affordable (Green) + 6 Market Rate (Blue)
A14: 5 | B14: Coral Village | C14: Cape Coral, FL | D14: 1999 | E14: 72 | F14: Section 8/HUD | G14: 48 - Coral Village | H14: 1BR / 2BR | I14: 3 Affordable (Green) + 6 Market Rate (Blue)
A15: 6 | B15: Holiday Apts | C15: Natchez, MS | D15: 1951 | E15: 115 | F15: Section 8/HUD | G15: 15 - Holiday | H15: 2BR / 3BR / 4BR / 5BR | I15: 3 Affordable (Green) + 6 Market Rate (Blue)
A16: 7 | B16: Cumberland | C16: Crystal Springs, MS | D16: 1985 | E16: 68 | F16: Section 8/HUD | G16: 16 - Cumberland | H16: 1BR / 2BR / 3BR / 4BR | I16: 3 Affordable (Green) + 6 Market Rate (Blue)
A17: 8 | B17: Village Green | C17: Natchez, MS | D17: 1977 | E17: 80 | F17: Section 8/HUD | G17: 17 - Village Green | H17: 1BR / 2BR / 3BR | I17: 3 Affordable (Green) + 6 Market Rate (Blue)
A18: 9 | B18: Walnut Hill | C18: Natchez, MS | D18: 1975 | E18: 168 | F18: Section 8/HUD | G18: 59 - Walnut Hill | H18: 2BR / 3BR | I18: 3 Affordable (Green) + 6 Market Rate (Blue)
A19: 10 | B19: River Pointe | C19: Columbus, OH | D19: 1996 | E19: 160 | F19: Section 8/HUD | G19: 29 - River Pointe | H19: 1BR / 2BR | I19: 3 Affordable (Green) + 6 Market Rate (Blue)
A20: 11 | B20: Breckenridge Village | C20: Ennis, TX | D20: 1997 | E20: 66 | F20: LIHTC | G20: 12 - Breckenridge | H20: 2BR / 4BR | I20: 3 Affordable (Green) + 6 Market Rate (Blue)
A21: 12 | B21: Lexington Arms | C21: Waxahachie, TX | D21: 1997 | E21: 61 | F21: LIHTC | G21: 38 - Lexington | H21: 2BR / 4BR | I21: 3 Affordable (Green) + 6 Market Rate (Blue)
... A24: 15 | B24: La Promesa | C24: Odessa, TX | D24: 1978 | E24: 136 | F24: Layered HUD/LIHTC | G24: 60 - La Promesa | H24: 2BR / 3BR | I24: 3 Affordable (Green) + 6 Market Rate (Blue)
A25: 16 | B25: New Wilmington Arms | C25: Compton, CA | D25: 1973 | E25: N/A | F25: Section 8/HUD | G25: 3 - Wilmington | H25: 1BR / 2BR / 3BR / 4BR | I25: 3 Affordable (Green) + 6 Market Rate (Blue)
A26: 17 | B26: Gates on Manhattan | C26: Harvey, LA | D26: 1968 | E26: 276 | F26: Section 8/HUD | G26: 19 - Gates | H26: 1BR / 2BR / 3BR | I26: 3 Affordable (Green) + 6 Market Rate (Blue)
A27: 18 | B27: Ruby Diamond | C27: Marrero, LA | D27: 2000 | E27: 73 | F27: LIHTC | G27: 42 - Ruby | H27: 3BR / 4BR | I27: 3 Affordable (Green) + 6 Market Rate (Blue)
A28: 19 | B28: Star Homes | C28: Marrero, LA | D28: 2000 | E28: 48 | F28: LIHTC | G28: 39 - Star | H28: 2BR / 3BR / 4BR | I28: 3 Affordable (Green) + 6 Market Rate (Blue)
A29: 20 | B29: Colonial Estates (Thibodaux) | C29: Thibodaux, LA | D29: 1975 | E29: 107 | F29: Section 8/HUD | G29: 20 - Thibodaux | H29: 1BR / 2BR / 3BR | I29: 3 Affordable (Green) + 6 Market Rate (Blue)
A30: 21 | B30: Marrero 3 | C30: Harvey, LA | D30: 1968 | E30: 173 | F30: Section 8/HUD | G30: 40 - Marrero | H30: 3BR / 4BR | I30: 3 Affordable (Green) + 6 Market Rate (Blue)
A31: 22 | B31: Arbor Crest | C31: Quincy, FL | D31: 1995 | E31: 120 | F31: LIHTC | G31: 37 - Arbor Crest | H31: 1BR / 2BR / 3BR | I31: 3 Affordable (Green) + 6 Market Rate (Blue)
A32: 23 | B32: Windsor/Yorkshire | C32: Shreveport, LA | D32: 1998 | E32: 134 | F32: LIHTC | G32: 33 - Windsor-Yorkshire | H32: 1BR / 2BR / 4BR | I32: 3 Affordable (Green) + 6 Market Rate (Blue)
A33: 24 | B33: North Pointe | C33: Bossier City, LA | D33: 2000 | E33: 27 | F33: LIHTC | G33: 50 - North Pointe | H33: 2BR / 3BR / 4BR | I33: 3 Affordable (Green) + 6 Market Rate (Blue)
A34: 25 | B34: Granite Bayou | C34: Baton Rouge, LA | D34: 2000 | E34: 60 | F34: LIHTC | G34: 53 - Bayou Pointe | H34: 3BR / 4BR | I34: 3 Affordable (Green) + 6 Market Rate (Blue)
A35: 26 | B35: St. Charles Place | C35: Lake Charles, LA | D35: 1995 | E35: 121 | F35: Layered HUD/LIHTC | G35: 41 - St. Charles | H35: 2BR / 3BR | I35: 3 Affordable (Green) + 6 Market Rate (Blue)
A36: 27 | B36: Pelican Bay | C36: Baton Rouge, LA | D36: 2001 | E36: 152 | F36: Section 8/HUD | G36: 55 - Pelican Bay | H36: 1BR / 2BR / 3BR / 4BR | I36: 3 Affordable (Green) + 6 Market Rate (Blue)
A37: 28 | B37: Howell Place | C37: Baton Rouge, LA | D37: 2001 | E37: 48 | F37: Section 8/HUD | G37: 56 - Howell Place | H37: 1BR / 2BR / 3BR / 4BR | I37: 3 Affordable (Green) + 6 Market Rate (Blue)
... A50: 42 | B50: Thomasville Church Homes | C50: Thomasville, NC | D50: 1975 | E50: 100 | F50: Section 8/HUD | G50: 44 - Thomasville | H50: 1BR / 2BR / 3BR / 4BR | I50: 3 Affordable (Green) + 6 Market Rate (Blue)
A51: 43 | B51: Crossroadsof Lee Summit

Sheet Excel Sharepoints
A1: Building Name | B1: Excel Rent Roll - Sharepoint URL
A2: Boca Ciega | B2: Boca Ciega Rent Roll - 06-15-2026.xls | D2: — | E2: — | F2: 1736 | G2: 2376 | H2: — | I2: —
A3: Jefferson | B3: JeffersonRentRoll.xls | D3: — | E3: — | F3: 1020 | G3: 1150 | H3: — | I3: —
A4: Opa Locka | D4: — | E4: 1470 | F4: 1800 | G4: 2320 | H4: — | I4: —
A5: Macedonia | D5: — | E5: — | F5: 1451 | G5: 1613 | H5: — | I5: —
A6: Coral Village | B6: Coral Village - Rent Roll - 06-15-2026.xls | D6: — | E6: 1375 | F6: 1552 | G6: — | H6: — | I6: —
A7: Holiday | B7: Holiday Rent Roll 06-29-2026.xls | D7: — | E7: — | F7: 935 | G7: 1073 | H7: 1147
A8: Cumberland | B8: Cumberland Rent Roll 06-29-2026.xls | D8: — | E8: 1074 | F8: 1166 | G8: 1290 | H8: 1433 | I8: —
A9: Walnut Hill | B9: Walnut Hill Rent Roll 06-29-2026.xls | D9: — | E9: — | F9: 1346 | G9: 1465 | H9: — | I9: —
A10: River Pointe | B10: River Pointe Rent Roll 06-29-2026.xlsx | D10: — | F10: 1400 | G10: — | H10: — | I10: —
A11: Breckenridge | B11: Breckenridge Rent Roll 06-29-2026.xls | D11: — | E11: — | F11: 964 | G11: — | H11: 1221 | I11: —
A12: Lexington | B12: Lexington Rent Roll 06-29-2026.xls | D12: — | E12: — | F12: 964 | G12: — | H12: 1221 | I12: —
A13: Grace Townhomes | B13: Grace Townhomes Rent Roll 06-29-2026.xls | D13: — | E13: 1198 | F13: 1430 | G13: 1656 | H13: — | I13: —
A14: Grove Park | B14: Grove Park Rent Roll 06-29-2026.xls | D14: — | E14: 1210 | F14: 1450 | G14: 1700 | H14: — | I14: —
A15: La Promesa | B15: La Promesa Rent Roll 06-29-2026.xlsx | D15: — | E15: — | F15: 1402 | G15: 1679 | H15: — | I15: —
A16: New Wilmington Arms | B16: New Wilmington Arms Rent Roll 06-29-2026.xls | D16: — | E16: 1221 | F16: 1563 | G16: 1820 | H16: 2128 | I16: —
A17: Gates of Manhattan | B17: Gates of Manhattan Rent Roll 06-29-2026.xlsx | D17: — | E17: 1000 | F17: 1150 | G17: 1300 | H17: — | I17: —
A18: Ruby | B18: Ruby Diamond - Rent Roll 06-12-2026.xlsx | D18: — | E18: — | G18: 1223 | H18: 870 | I18: —
A19: Star | B19: Star - Rent Roll 06-12-2026.xlsx | D19: — | E19: — | F19: 894 | G19: 982 | H19: 1045 | I19: —
A20: Marrero | B20: Marrero - Rent Roll Detail 06-12-2026.xls | D20: — | E20: — | G20: 1401 | H20: 1563 | I20: —
A21: Arbor Crest | B21: Arbor Crest - Rent Roll - 06-15-2026.xls | D21: — | E21: 914 | F21: 1058 | G21: 1204 | H21: — | I21: —
A22: Windsor-Yorkshire | B22: Windsor - Thibodaux Rent Roll 06-29-2026.xls | C22: Yorkshire - Thibodaux Rent Roll 06-29-2026.xls | D22: — | E22: 777 | F22: 885 | G22: — | H22: 1140 | I22: —
A23: North Pointe | B23: North Pointe Rent Roll 06-29-2026.xls | D23: — | E23: — | F23: 575 | G23: 655 | H23: 695 | I23: —
A24: Bayou Pointe | B24: Bayou Pointe Rent Roll 06-29-2026.xls | D24: — | E24: — | F24: — | G24: 1053 | H24: 1152 | I24: —
A25: St. Charles | B25: St Charles Rent Roll 06-29-2026.xls | D25: — | E25: — | F25: 1154 | G25: 1484 | H25: — | I25: —
A26: Pelican Bay | B26: Pelican Bay Rent Roll 06-29-2026.xls | D26: — | E26: 874 | F26: 1039 | G26: 1194 | H26: 1321 | I26: —
A27: Howell Place | B27: Howell Place Rent Roll 06-29-2026.xls | D27: — | E27: 874 | F27: 1039 | G27: 1194 | H27: 1321 | I27: —
A28: Pirates Bend | B28: Pirates Bend Rent Roll 06-29-2026.xls | D28: — | E28: 874 | F28: 1039 | G28: 1194 | H28: 1321 | I28: —
A29: Anaheim Gardens | B29: Anaheim Gardens Rent Roll 06-29-2026.xls | D29: — | E29: 3374 | F29: 3979 | G29: 4973 | H29: — | I29: —
A30: Fairfax | B30: Fairfax - Rent Roll - 06-15-2026.xls | D30: — | E30: 2908 | F30: — | G30: — | H30: — | I30: —
A31: Urban | B31: Urban Rehab Rent Roll 06-29-2026.xls | D31: — | E31: — | F31: 1842 | G31: — | H31: — | I31: —
A32: Midtown | B32: Midtown Manor Rent Roll 06-29-2026.xls | D32: — | E32: 1612 | F32: — | G32: — | H32: — | I32: —
A33: Pacific Pointe | B33: Pacific Pointe Rent Roll 06-29-2026.xls | D33: — | E33: 1252 | F33: 1374 | G33: — | H33: — | I33: —
A34: Granite Ridge | B34: Granite Ridge Rent Roll 06-29-2026.xls | D34: — | E34: 1212 | F34: 1383 | G34: — | H34: — | I34: —
A35: Columbia | B35: Columbia Village Rent Roll 06-29-2026.xlsx | D35: — | E35: — | F35: 1364 | G35: 1577.5 | H35: 1731 | I35: —
A36: Forest View | B36: Forest View Rent Roll 06-29-2026.xlsx | D36: — | E36: 723.88 | F36: 855.17 | G36: — | H36: — | I36: —
A37: Oak Hills | B37: Oak Hills Rent Roll 06-29-2026.xlsx | D37: — | E37: — | F37: 1308 | G37: 1526.47 | H37: — | I37: —
A38: River Garden | B38: River Gardens Rent Roll 06-29-2026.xlsx | D38: — | E38: — | F38: 1140 | G38: 1317 | H38: 1470 | I38: 1784
A39: Silver Springs | B39: Silver Springs Rent Roll 06-29-2026.xls | D39: — | E39: 970 | F39: 1185 | G39: 1400 | H39: 1695 | I39: —
A40: Thomasville | B40: Thomasville Rent Roll 06-29-2026.xls | D40: — | E40: 946 | F40: 1054 | G40: 1328 | H40: 1425 | I40: —
...

Sheet Current Rents
A8: As of June 2026 | Enter rents here — values flow automatically to each building sheet | K8: Property (Sheet Name) | L8: Bed Type | M8: Current Rent | O8: Property (Sheet Name) | P8: Bed Type | Q8: Current Rent | S8: Property (Sheet Name) | T8: Bed Type | U8: Current Rent
A9: As of June 2026 | All values are live formula links — update rent on the building sheet and it updates here automatically | K9: Same information that is in the table to the left.
A10: ID | B10: Property Name | C10: Studio (0BD) | D10: 1 Bed (1BD) | E10: 2 Bed (2BD) | F10: 3 Bed (3BD) | G10: 4 Bed (4BD) | H10: 5 Bed (5BD) | I10: Notes | K10: 21 - Boca Ciega | L10: 2BD | M10: 1736 | O10: 42 - Ruby | P10: 3BD | Q10: 1223 | S10: 25 - Columbia | T10: 2BD | U10: 1364
A11: 21 | B11: Boca Ciega | C11: — | D11: — | E11: 1736 | F11: 2376 | G11: — | H11: — | K11: 21 - Boca Ciega | L11: 3BD | M11: 2376 | O11: 42 - Ruby | P11: 4BD | Q11: 870 | S11: 25 - Columbia | T11: 3BD | U11: 1577.5
A12: 13 | B12: Jefferson | C12: — | D12: — | E12: 1020 | F12: 1150 | G12: — | H12: — | K12: 13 - Jefferson | L12: 2BD | M12: 1020 | O12: 39 - Star | P12: 2BD | Q12: 894 | S12: 25 - Columbia | T12: 4BD | U12: 1731
A13: 18 | B13: Opa Locka | C13: — | D13: 1470 | E13: 1800 | F13: 2320 | G13: — | H13: — | K13: 13 - Jefferson | L13: 3BD | M13: 1150 | O13: 39 - Star | P13: 3BD | Q13: 982 | S13: 26 - Forest View | T13: 1BD | U13: 723.88
A14: 14 | B14: Macedonia | C14: — | D14: — | E14: 1451 | F14: 1613 | G14: — | H14: — | K14: 18 - Opa Locka (135th Apartments) | L14: 1BD | M14: 1470 | O14: 39 - Star | P14: 4BD | Q14: 1045 | S14: 26 - Forest View | T14: 2BD | U14: 855.17
A15: 48 | B15: Coral Village | C15: — | D15: 1375 | E15: 1552 | F15: — | G15: — | H15: — | K15: 19 - Opa Locka (135th Apartments) | L15: 2BD | M15: 1800 | O15: 40 - Marrero | P15: 3BD | Q15: 1401 | S15: 24 - Oak Hills | T15: 2BD | U15: 1308
A16: 15 | B16: Holiday | C16: — | D16: — | E16: 935 | F16: 1073 | G16: 1147 | K16: 20 - Opa Locka (135th Apartments) | L16: 3BD | M16: 2320 | O16: 40 - Marrero | P16: 4BD | Q16: 1563 | S16: 24 - Oak Hills | T16: 3BD | U16: 1526.47
A17: 16 | B17: Cumberland | C17: — | D17: 1074 | E17: 1166 | F17: 1290 | G17: 1433 | H17: — | K17: 14 - Macedonia | L17: 2BD | M17: 1451 | O17: 37 - Arbor Crest | P17: 1BD | Q17: 914 | S17: 58 - River Garden | T17: 2BD | U17: 1140
A18: 59 | B18: Walnut Hill | C18: — | D18: — | E18: 1346 | F18: 1465 | G18: — | H18: — | K18: 14 - Macedonia | L18: 3BD | M18: 1613 | O18: 37 - Arbor Crest | P18: 2BD | Q18: 1058 | S18: 58 - River Garden | T18: 3BD | U18: 1317
A19: 29 | B19: River Pointe | C19: — | E19: 1400 | F19: — | G19: — | H19: — | K19: 48 - Coral Village | L19: 1BD | M19: 1375 | O19: 37 - Arbor Crest | P19: 3BD | Q19: 1204 | S19: 58 - River Garden | T19: 4BD | U19: 1470
A20: 12 | B20: Breckenridge | C20: — | D20: — | E20: 964 | F20: — | G20: 1221 | H20: — | K20: 48 - Coral Village | L20: 2BD | M20: 1552 | O20: 33 - Windsor-Yorkshire | P20: 1BD | Q20: 777 | S20: 58 - River Garden | T20: 5BD | U20: 1784
A21: 38 | B21: Lexington | C21: — | D21: — | E21: 964 | F21: — | G21: 1221 | H21: — | K21: 15 - Holiday | L21: 2BD | M21: 935 | O21: 33 - Windsor-Yorkshire | P21: 2BD | Q21: 885 | S21: 36 - Silver Springs | T21: 1BD | U21: 970
A22: 23 | B22: Grace Townhomes | C22: — | D22: 1198 | E22: 1430 | F22: 1656 | G22: — | H22: — | K22: 15 - Holiday | L22: 3BD | M22: 1073 | O22: 33 - Windsor-Yorkshire | P22: 4BD | Q22: 1140 | S22: 36 - Silver Springs | T22: 2BD | U22: 1185
A23: 46 | B23: Grove Park | C23: — | D23: 1210 | E23: 1450 | F23: 1700 | G23: — | H23: — | K23: 15 - Holiday | L23: 4BD | M23: 1147 | O23: 50 - North Pointe | P23: 2BD | Q23: 575 | S23: 36 - Silver Springs | T23: 3BD | U23: 1400
A24: 60 | B24: La Promesa | C24: — | D24: — | E24: 1402 | F24: 1679 | G24: — | H24: — | K24: 16 - Cumberland | L24: 1BD | M24: 1074 | O24: 50 - North Pointe | P24: 3BD | Q24: 655 | S24: 36 - Silver Springs | T24: 4BD | U24: 1695
A25: 3 | B25: Wilmington | C25: — | D25: 1221 | E25: 1563 | F25: 1820 | G25: 2128 | H25: — | K25: 16 - Cumberland | L25: 2BD | M25: 1166 | O25: 50 - North Pointe | P25: 4BD | Q25: 695 | S25: 36 - Silver Springs | T25: 5BD | U25: 970
A26: 19 | B26: Gates | C26: — | D26: 1000 | E26: 1150 | F26: 1300 | G26: — | H26: — | K26: 16 - Cumberland | L26: 3BD | M26: 1290 | O26: 53 - Bayou Pointe | P26: 3BD | Q26: 1053 | S26: 44 - Thomasville | T26: 1BD | U26: 946
A27: 42 | B27: Ruby | C27: — | D27: — | F27: 1223 | G27: 870 | H27: — | K27: 16 - Cumberland | L27: 4BD | M27: 1433 | O27: 53 - Bayou Pointe | P27: 4BD | Q27: 1152 | S27: 44 - Thomasville | T27: 2BD | U27: 1054
A28: 39 | B28: Star | C28: — | D28: — | E28: 894 | F28: 982 | G28: 1045 | H28: — | K28: 59 - Walnut Hill | L28: 2BD | M28: 1346 | O28: 41 - St. Charles | P28: 2BD | Q28: 1154 | S28: 44 - Thomasville | T28: 3BD | U28: 1328
A29: 20 | B29: See Windsor/Yorkshire | K29: 59 - Walnut Hill | L29: 3BD | M29: 1465 | O29: 41 - St. Charles | P29: 3BD | Q29: 1484 | S29: 44 - Thomasville | T29: 4BD | U29: 1425
A30: 40 | B30: Marrero | C30: — | D30: — | F30: 1401 | G30: 1563 | H30: — | K30: 29 - River Pointe | L30: 2BD | M30: 1400 | O30: 55 - Pelican Bay | P30: 1BD | Q30: 874 | S30: 44 - Thomasville | T30: 1BD | U30: 946
A31: 37 | B31: Arbor Crest | C31: — | D31: 914 | E31: 1058 | F31: 1204 | G31: — | H31: — | K31: 29 - River Pointe | L31: 3BD | M31: 1600 | O31: 55 - Pelican Bay | P31: 2BD | Q31: 1039 | S31: 44 - Thomasville | T31: 2BD | U31: 1054
A32: 33 | B32: Windsor-Yorkshire | C32: — | D32: 777 | E32: 885 | F32: — | G32: 1140 | H32: — | K32: 29 - River Pointe | L32: 4BD | M32: 1700 | O32: 55 - Pelican Bay | P32: 3BD | Q32: 1194 | S32: 44 - Thomasville | T32: 3BD | U32: 1328
A33: 50 | B33: North Pointe | C33: — | D33: — | E33: 575 | F33: 655 | G33: 695 | H33: — | K33: 12 - Breckenridge | L33: 2BD | M33: 964 | O33: 55 - Pelican Bay | P33: 4BD | Q33: 1321 | S33: 63 - Crossroads | T33: 2BD | U33: 1388
A34: 53 | B34: Bayou Pointe | C34: — | D34: — | E34: — | F34: 1053 | G34: 1152 | H34: — | K34: 12 - Breckenridge | L34: 4BD | M34: 1221 | O34: 56 - Howell Place | P34: 1BD | Q34: 874 | S34: 63 - Crossroads | T34: 3BD | U34: 1592
A35: 41 | B35: St. Charles | C35: — | D35: — | E35: 1154 | F35: 1484 | G35: — | H35: — | K35: 38 - Lexington | L35: 2BD | M35: 964 | O35: 56 - Howell Place | P35: 2BD
A36: 55 | B36: Pelican Bay | C36: — | D36: 874 | E36: 1039 | F36: 1194 | G36: 1321 | H36: — | K36: 38 - Lexington | L36: 4BD | M36: 1221 | O36: 56 - Howell Place | P36: 3BD
A37: 56 | B37: Howell Place | C37: — | D37: 874 | E37: 1039 | F37: 1194 | G37: 1321 | H37: — | K37: 23 - Grace Townhomes | L37: 1BD | M37: 1198 | O37: 56 - Howell Place | P37: 4BD
A38: 57 | B38: Pirates Bend | C38: — | D38: 874 | E38: 1039 | F38: 1194 | G38: 1321 | H38: — | K38: 23 - Grace Townhomes | L38: 2BD | M38: 1430 | O38: 57 - Pirates Bend | P38: 1BD
A39: 6 | B39: Anaheim Gardens | C39: — | D39: 3374 | E39: 3979 | F39: 4973 | G39: — | H39: — | K39: 23 - Grace Townhomes | L39: 3BD | M39: 1656 | O39: 57 - Pirates Bend | P39: 2BD
A40: 11 | B40: Fairfax | C40: — | D40: 2908 | E40: — | F40: — | G40: — | H40: — | K40: 46 - Grove Park | L40: 1BD | M40: 1210 | O40: 57 - Pirates Bend | P40: 3BD
A41: 31 | B41: Urban | C41: — | D41: — | E41: 1842 | F41: — | G41: — | H41: — | K41: 46 - Grove Park | L41: 2BD | M41: 1450 | O41: 57 - Pirates Bend | P41: 4BD
A42: 2 | B42: Midtown | C42: — | D42: 1612 | E42: — | F42: — | G42: — | H42: — | K42: 46 - Grove Park | L42: 3BD | M42: 1700 | O42: 6 - Anaheim Gardens | P42: 1BD
A43: 34 | B43: Pacific Pointe | C43: — | D43: 1252 | E43: 1374 | F43: — | G43: — | H43: — | K43: 60 - La Promesa | L43: 2BD | M43: 1402 | O43: 6 - Anaheim Gardens | P43: 2BD
A44: 28 | B44: Granite Ridge | C44: — | D44: 1212 | E44: 1383 | F44: — | G44: — | H44: — | K44: 60 - La Promesa | L44: 3BD | M44: 1679 | O44: 6 - Anaheim Gardens | P44: 3BD
A45: 25 | B45: Columbia | C45: — | D45: — | E45: 1364 | F45: 1577.5 | G45: 1731 | H45: — | K45: 3 - Wilmington | L45: 1BD | M45: 1221 | O45: 11 - Fairfax | P45: 1BD
A46: 26 | B46: Forest View | C46: — | D46: 723.88 | E46: 855.17 | F46: — | G46: — | H46: — | K46: 3 - Wilmington | L46: 2BD | M46: 1563 | O46: 31 - Urban | P46: 0BD
A47: 24 | B47: Oak Hills | C47: — | D47: — | E47: 1308 | F47: 1526.47 | G47: — | H47: — | K47: 3 - Wilmington | L47: 3BD | M47: 1820 | O47: 31 - Urban | P47: 2BD
...

Sheet 21 - Boca Ciega
A2: RENT COMPARABLES ANALYSIS — BOCA CIEGA | ST. PETERSBURG, FL 33711 | Z2: 21 - Boca Ciega | 109 Units | LIHTC / Section 8 | 2BD & 3BD
A3: 3401 37th Street South, St. Petersburg, FL 33711 | Pinellas County | Tampa-St. Petersburg MSA | FY2026 FMR: 2BD $2,170 / 3BD $2,780
A4: Data as of April 30, 2026 | Sources: Apartments.com, HUD FMR Database, HUD Multifamily Assisted Housing, Apartment Corp Records
A5: COLUMN GUIDE — Income-restricted comps show AMI-based maximum allowable rents at 50% and 60% AMI tiers. Market-rate comps show what unrestricted renters pay in the same market. LOW = 50% AMI max rent. MID = 60% AMI max rent. FMR = HUD FY2026 Fair Market Rent (40th percentile). ACTUAL = Verified advertised rent from Apartments.com (highlighted in orange). 'Not Listed' = property does not publicly advertise rents. AMI source: HUD FY2025 MTSP Income Limits, effective April 1, 2025.
A6: Rank | B6: Type | C6: Property Name | E6: Address | F6: City | G6: St | H6: ZIP | I6: Distance | J6: 2BD 50% AMI | K6: 2BD 60% AMI | L6: 2BD FMR | M6: 2BD - Actual | N6: 3BD 50% AMI | O6: 3BD 60% AMI | P6: 3BD FMR | Q6: 3BD - Actual | R6: Units | S6: Yr Built | T6: Yr Diff | U6: Utils Incl. | V6: Pet Friendly | W6: Gated | X6: Pool | Y6: W/D In-Unit | Z6: Competition Level | AA6: Notes / Why Competitive | AB6: Data Source
A7: ★ | B7: SUBJECT | C7: Boca Ciega (SUBJECT) | E7: 3401 37th Street South | F7: St. Petersburg | G7: FL | H7: 33711 | I7: 0.0 mi | J7: $3,912 | K7: $4,695 | L7: $2,170 | M7: 1736 | N7: $4,345 | O7: $5,215 | P7: $2,780 | Q7: 2376 | R7: 109 | S7: 2015 | T7: 0 | U7: Yes | V7: No | W7: No | X7: No | Y7: No | Z7: SUBJECT | AA7: 109 units | Layered HUD/LIHTC. Year built: 1974. Subject property. | AB7: Apartment Corp Records
A8: 1 | B8: AFFORDABLE | C8: Clearwater Gardens Apartments | E8: 1501 N Greenwood Ave | F8: Clearwater | G8: FL | H8: 33755 | I8: 14.2 mi | J8: $3,912 | K8: $4,695 | L8: $2,170 | M8: Not Listed | N8: $4,345 | O8: $5,215 | P8: $2,780 | Q8: Not Listed | R8: 100 | S8: 1974 | T8: 0 | U8: Yes | V8: No | W8: No | X8: No | Y8: No | Z8: HIGH | AA8: Section 8/HUD, 1974 vintage, 100 units, 14.2 mi. | AB8: HUD Multifamily Assisted Housing
A9: 2 | B9: AFFORDABLE | C9: Pinellas Park Manor | E9: 6200 Park Blvd | F9: Pinellas Park | G9: FL | H9: 33781 | I9: 7.1 mi | J9: $3,912 | K9: $4,695 | L9: $2,170 | M9: Not Listed | N9: $4,345 | O9: $5,215 | P9: $2,780 | Q9: Not Listed | R9: 112 | S9: 1975 | T9: 1 | U9: Yes | V9: No | W9: No | X9: No | Y9: No | Z9: HIGH | AA9: Section 8/HUD, 1975 vintage, 112 units, 7.1 mi. | AB9: HUD Multifamily Assisted Housing
A10: 3 | B10: AFFORDABLE | C10: Tarpon Springs Housing Authority | E10: 200 S Walton Ave | F10: Tarpon Springs | G10: FL | H10: 34689 | I10: 22.5 mi | J10: $3,912 | K10: $4,695 | L10: $2,170 | M10: Not Listed | N10: $4,345 | O10: $5,215 | P10: $2,780 | Q10: Not Listed | R10: 96 | S10: 1972 | T10: 2 | U10: Yes | V10: No | W10: No | X10: No | Y10: No | Z10: MODERATE-HIGH | AA10: Public Housing/HUD, 1972 vintage, 96 units, 22.5 mi. | AB10: Tarpon Springs Housing Authority
A11: 1 | B11: MARKET RATE | C11: Addison at Bayfront | D11: COMPETITION | E11: 2800 1st Ave S | F11: St. Petersburg | G11: FL | H11: 33712 | I11: 1.2 mi | J11: N/A | K11: N/A | L11: $2,170 | M11: 2446 | N11: N/A | O11: N/A | P11: $2,780 | Q11: 2947 | R11: 266 | S11: 2020 | T11: 5 | U11: No | V11: Yes | W11: No | X11: Yes | Y11: Yes | Z11: HIGH | AA11: No income restrictions, 2020 vintage, 266 units, 1.2 mi. 2BD $2,446 / 3BD $2,947. | AB11: apartments.com/addison-at-bayfront-saint-petersburg-fl/
A12: 2 | B12: MARKET RATE | C12: Marina Walk at One Waterfront | E12: 101 1st Ave S | F12: St. Petersburg | G12: FL | H12: 33701 | I12: 2.8 mi | J12: N/A | K12: N/A | L12: $2,170 | M12: 2600 | N12: N/A | O12: N/A | P12: $2,780 | Q12: N/A | R12: 163 | S12: 2023 | T12: 8 | U12: No | V12: Yes | W12: Yes | X12: Yes | Y12: Yes | Z12: HIGH | AA12: No income restrictions, 2023 vintage, 163 units, 2.8 mi. 2BD $2,600. | AB12: apartments.com/marina-walk-at-one-waterfront-saint-petersburg-fl/
A13: 3 | B13: MARKET RATE | C13: Flagler Pointe | E13: 3001 Gandy Blvd N | F13: St. Petersburg | G13: FL | H13: 33702 | I13: 1.9 mi | J13: N/A | K13: N/A | L13: $2,170 | M13: 1890 | N13: N/A | O13: N/A | P13: $2,780 | Q13: 2150 | R13: N/A | S13: 1974 | T13: 0 | U13: No | V13: Yes | W13: No | X13: Yes | Y13: No | Z13: HIGH | AA13: No income restrictions, 1974 vintage, 1.9 mi. 2BD $1,890 / 3BD $2,150. | AB13: apartments.com/flagler-pointe-apartments-saint-petersburg-fl/
A14: 4 | B14: MARKET RATE | C14: Sur Club | E14: 3301 32nd Ave S | F14: St. Petersburg | G14: FL | H14: 33712 | I14: 1.5 mi | J14: N/A | K14: N/A | L14: $2,170 | M14: 2250 | N14: N/A | O14: N/A | P14: $2,780 | Q14: N/A | R14: 296 | S14: 2021 | T14: 47 | U14: No | V14: Yes | W14: No | X14: Yes | Y14: Yes | Z14: HIGH | AA14: No income restrictions, 2021 vintage, 296 units, 1.5 mi. 2BD $2,250. | AB14: apartments.com/sur-club-saint-petersburg-fl/
A15: 5 | B15: MARKET RATE | C15: Lake Maggiore | E15: 825 32nd Ave S | F15: St. Petersburg | G15: FL | H15: 33705 | I15: 2.1 mi | J15: N/A | K15: N/A | L15: $2,170 | M15: 2520 | N15: N/A | O15: N/A | P15: $2,780 | Q15: 3840 | R15: 330 | S15: 2023 | T15: 8 | U15: No | V15: Yes | W15: Yes | X15: Yes | Y15: Yes | Z15: HIGH | AA15: No income restrictions, 2023 vintage, 330 units, 2.1 mi. 2BD $2,520 / 3BD $3,840. | AB15: apartments.com/lake-maggiore-saint-petersburg-fl/
A16: 6 | B16: MARKET RATE | C16: The Courtney at Bay Pines | E16: 4652 Miramar Dr | F16: St. Petersburg | G16: FL | H16: 33708 | I16: 5.2 mi | J16: N/A | K16: N/A | L16: $2,170 | M16: 2310 | N16: N/A | O16: N/A | P16: $2,780 | Q16: 2755 | R16: 312 | S16: 2013 | T16: 2 | U16: No | V16: Yes | W16: Yes | X16: Yes | Y16: Yes | Z16: HIGH | AA16: No income restrictions, 2013 vintage, 312 units, 5.2 mi. 2BD $2,310 / 3BD $2,755. | AB16: apartments.com/the-courtney-at-bay-pines-saint-petersburg-fl/
A17: — | B17: BENCHMARK | C17: FY2026 FMR — Tampa-St. Petersburg MSA | E17: N/A | F17: St. Petersburg | G17: FL | H17: N/A | I17: N/A | J17: $2,170 | K17: $2,170 | L17: $2,170 | M17: N/A | N17: $2,780 | O17: $2,780 | P17: $2,780 | Q17: N/A | R17: N/A | S17: N/A | T17: N/A | U17: N/A | V17: N/A | W17: N/A | X17: N/A | Y17: N/A | Z17: BENCHMARK | AA17: HUD FMR for Tampa-St. Petersburg MSA, FY2026. 40th percentile of gross rents. | AB17: HUD FMR Database (huduser.gov)
A18: — | B18: BENCHMARK | C18: Metro Market Avg — St. Petersburg (Apr 2026) | E18: N/A | F18: St. Petersburg | G18: FL | H18: N/A | I18: N/A | J18: $2,336 | K18: $2,336 | L18: $2,336 | M18: $2,336 | N18: $2,923 | O18: $2,923 | P18: $2,923 | Q18: $2,923 | R18: N/A | S18: N/A | T18: N/A | U18: N/A | V18: N/A | W18: N/A | X18: N/A | Y18: N/A | Z18: BENCHMARK | AA18: Live Market Average from 6 market-rate comps, Apr 30, 2026. 2BD avg $2,336 / 3BD avg $2,923. | AB18: Apartments.com live data, Apr 30, 2026
A20: COLOR KEY: GREEN = Subject Property | TEAL = Affordable/Income-Restricted Comps | BLUE = Market Rate Comps | ORANGE = Actual Advertised Rent | YELLOW = Market Average Benchmark
A22: CURRENT RENT vs. MARKET AVERAGE
A23: Market Average = Avg of Actual Advertised Rents from 6 Market-Rate Comps (Apartments.com)
B24: Current Rents | C24: Market Avg | E24: Difference
A25: 2BD | B25: 1736 | C25: 2336 | E25: =B25-C25 -> -600 | F25: =IF(E25<-75,"LOOK INTO INCREASING THE RENT!","") -> LOOK INTO INCREASING THE RENT!
A26: 3BD | B26: 2376 | C26: 2923 | E26: =B26-C26 -> -547 | F26: =IF(E26<-75,"LOOK INTO INCREASING THE RENT!","") -> LOOK INTO INCREASING THE RENT!

Sheet 13 - Jefferson
A2: RENT COMPARABLES ANALYSIS — JEFFERSON ARMS | MONTICELLO, FL 32344 | Z2: 13 - Jefferson | 60 Units | LIHTC / Section 8 | 2BD & 3BD
A3: 1001 W Washington St, Monticello, FL 32344 | Jefferson County
A4: Data as of June 16, 2026 | Sources: Apartments.com, HUD FMR Database, Apartment Corp Records
A5: COLUMN GUIDE — Income-restricted comps show AMI-based maximum rents (50%/60% AMI) alongside FMR. Market-rate comps show N/A for AMI columns. Actual = advertised/in-place rent. Competition Level: HIGH = direct competition; MODERATE-HIGH = partial overlap.
A6: Rank | B6: Type | C6: Property Name | E6: Address | F6: City | G6: St | H6: ZIP | I6: Distance | J6: 2BD 50% AMI | K6: 2BD 60% AMI | L6: 2BD FMR | M6: 2BD - Actual | N6: 3BD 50% AMI | O6: 3BD 60% AMI | P6: 3BD FMR | Q6: 3BD - Actual | R6: Units | S6: Yr Built | T6: Yr Diff | U6: Utils Incl. | V6: Pet Friendly | W6: Gated | X6: Pool | Y6: W/D In-Unit | Z6: Competition Level | AA6: Notes / Why Competitive | AB6: Data Source
A7: ★ | B7: SUBJECT | C7: Jefferson (SUBJECT) | E7: 1001 W Washington St | F7: Monticello | G7: FL | H7: 32344 | I7: 0.0 mi | J7: $2,420 | K7: $2,904 | L7: $1,210 | M7: ='Current Rents'!E12 -> 1020 | N7: $2,797 | O7: $3,357 | P7: $1,540 | Q7: ='Current Rents'!F12 -> 1150 | R7: 60 | S7: 1971 | U7: Yes | V7: No | W7: No | X7: No | Y7: No | Z7: SUBJECT | AA7: 60 units | LIHTC/Section 8. Year built: 1971. Subject property. | AB7: Apartment Corp Records
A8: 1 | B8: AFFORDABLE | C8: Monticello Manor | E8: 500 S Jefferson St | F8: Monticello | G8: FL | H8: 32344 | I8: 0.5 mi | J8: $2,420 | K8: $2,904 | L8: $1,210 | M8: Not Listed | N8: $2,797 | O8: $3,357 | P8: $1,540 | Q8: Not Listed | R8: 40 | S8: 1972 | T8: 1 | U8: Yes | V8: No | W8: No | X8: No | Y8: No | Z8: HIGH | AA8: Section 8/HUD, 1972 vintage, 40 units, 0.5 mi. | AB8: HUD Multifamily Assisted Housing
A9: 2 | B9: AFFORDABLE | C9: Waukeenah Manor | E9: US-19, Waukeenah | F9: Waukeenah | G9: FL | H9: 32344 | I9: 8.0 mi | J9: $2,420 | K9: $2,904 | L9: $1,210 | M9: Not Listed | N9: $2,797 | O9: $3,357 | P9: $1,540 | Q9: Not Listed | R9: 24 | S9: 1974 | T9: 3 | U9: Yes | V9: No | W9: No | X9: No | Y9: No | Z9: HIGH | AA9: Section 8/HUD, 1974 vintage, 24 units, 8.0 mi. | AB9: HUD Multifamily Assisted Housing
A10: 3 | B10: AFFORDABLE | C10: Greenville Manor | E10: Hwy 221, Greenville | F10: Greenville | G10: FL | H10: 32331 | I10: 15.0 mi | J10: $2,420 | K10: $2,904 | L10: $1,210 | M10: Not Listed | N10: $2,797 | O10: $3,357 | P10: $1,540 | Q10: Not Listed | R10: 20 | S10: 1975 | T10: 4 | U10: Yes | V10: No | W10: No | X10: No | Y10: No | Z10: MODERATE-HIGH | AA10: Section 8/HUD, 1975 vintage, 20 units, 15.0 mi. | AB10: HUD Multifamily Assisted Housing
A11: 1 | B11: MARKET RATE | C11: Magnolia Terrace | D11: COMPETITION | E11: 1200 N Jefferson St | F11: Monticello | G11: FL | H11: 32344 | I11: 0.3 mi | J11: N/A | K11: N/A | L11: $1,210 | M11: 1250 | N11: N/A | O11: N/A | P11: $1,540 | Q11: 1450 | R11: 48 | S11: 1985 | T11: 14 | U11: No | V11: Yes | W11: No | X11: Yes | Y11: No | Z11: HIGH | AA11: No income restrictions, 1985 vintage, 48 units, 0.3 mi. 2BD avg $1,250/mo. | AB11: apartments.com/magnolia-terrace-monticello-fl/
A12: 2 | B12: MARKET RATE | C12: Jefferson Commons | E12: 450 E Pearl St | F12: Monticello | G12: FL | H12: 32344 | I12: 0.5 mi | J12: N/A | K12: N/A | L12: $1,210 | M12: 1195 | N12: N/A | O12: N/A | P12: $1,540 | Q12: 1395 | R12: 36 | S12: 1978 | T12: 7 | U12: No | V12: Yes | W12: No | X12: No | Y12: No | Z12: HIGH | AA12: No income restrictions, 1978 vintage, 36 units, 0.5 mi. 2BD avg $1,195/mo. | AB12: apartments.com/jefferson-commons-monticello-fl/
A13: 3 | B13: MARKET RATE | C13: Monticello Village Apts | E13: 300 S Cherry St | F13: Monticello | G13: FL | H13: 32344 | I13: 0.4 mi | J13: N/A | K13: N/A | L13: $1,210 | M13: 1100 | N13: N/A | O13: N/A | P13: $1,540 | Q13: 1350 | R13: 24 | S13: 1970 | U13: No | V13: No | W13: No | X13: No | Y13: No | Z13: HIGH | AA13: No income restrictions, 1970 vintage, 24 units, 0.4 mi. 2BD avg $1,100/mo. | AB13: apartments.com/monticello-village-fl/
A14: 4 | B14: MARKET RATE | C14: Tallahassee Crossing | E14: 4200 Apalachee Pkwy | F14: Tallahassee | G14: FL | H14: 32311 | I14: 26.0 mi | J14: N/A | K14: N/A | L14: $1,210 | M14: 1399 | N14: N/A | O14: N/A | P14: $1,540 | Q14: 1599 | R14: 312 | S14: 2005 | T14: 34 | U14: No | V14: Yes | W14: Yes | X14: Yes | Y14: Yes | Z14: HIGH | AA14: No income restrictions, 2005 vintage, 312 units, 26.0 mi. 2BD avg $1,399/mo. | AB14: apartments.com/tallahassee-crossing-fl/
A15: 5 | B15: MARKET RATE | C15: Arbor Station Apartments | E15: 4105 Arbor Hill Ln | F15: Tallahassee | G15: FL | H15: 32312 | I15: 28.0 mi | J15: N/A | K15: N/A | L15: $1,210 | M15: 1539 | N15: N/A | O15: N/A | P15: $1,540 | Q15: 1659 | R15: 252 | S15: 1990 | T15: 19 | U15: No | V15: Yes | W15: No | X15: Yes | Y15: Yes | Z15: HIGH | AA15: No income restrictions, 1990 vintage, 252 units, 28.0 mi. 2BD avg $1,539/mo. | AB15: apartments.com/arbor-station-apartments-tallahassee-fl/
A16: 6 | B16: MARKET RATE | C16: Capital Place at Southwood | E16: 2300 Bluff Oak Way | F16: Tallahassee | G16: FL | H16: 32311 | I16: 30.0 mi | J16: N/A | K16: N/A | L16: $1,210 | M16: N/A | N16: N/A | O16: N/A | P16: $1,540 | Q16: 1675 | R16: 288 | S16: 2013 | T16: 42 | U16: No | V16: Yes | W16: Yes | X16: Yes | Y16: Yes | Z16: HIGH | AA16: No income restrictions, 2013 vintage, 288 units, 30.0 mi. 3BD avg $1,675/mo. | AB16: apartments.com/capital-place-at-southwood-tallahassee-fl/
A17: — | B17: BENCHMARK | C17: FY2026 FMR — Jefferson County, FL | E17: N/A | F17: Monticello | G17: FL | H17: N/A | I17: N/A | J17: $1,210 | K17: $1,210 | L17: $1,210 | M17: N/A | N17: $1,540 | O17: $1,540 | P17: $1,540 | Q17: N/A | R17: N/A | S17: N/A | T17: N/A | U17: N/A | V17: N/A | W17: N/A | X17: N/A | Y17: N/A | Z17: BENCHMARK | AA17: HUD FMR for Jefferson County, FL, FY2026. 40th percentile rent. | AB17: HUD FMR Database (huduser.gov)
A18: — | B18: BENCHMARK | C18: Metro Market Avg — Monticello/Tallahassee (Apr 2026) | E18: N/A | F18: Monticello | G18: FL | H18: N/A | I18: N/A | J18: $1,380 | K18: $1,380 | L18: $1,380 | M18: $1,380 | N18: $1,507 | O18: $1,507 | P18: $1,507 | Q18: $1,507 | R18: N/A | S18: N/A | T18: N/A | U18: N/A | V18: N/A | W18: N/A | X18: N/A | Y18: N/A | Z18: BENCHMARK | AA18: Live Market Average from 6 market-rate comps, Apr 30, 2026. 2BD avg $1,380; 3BD avg $1,507. | AB18: Apartments.com live data, Apr 30, 2026
A20: COLOR KEY: GREEN = Subject Property | TEAL = Affordable/Income-Restricted Comp | BLUE = Market-Rate Comp | LIGHT BLUE = FMR Benchmark | YELLOW = Market Average | ORANGE = Actual Rent
A22: CURRENT RENT vs. MARKET AVERAGE
A23: Market Average = Avg of Actual Advertised Rents from 6 Market-Rate Comps (Apartments.com)
B24: Current Rents | C24: Market Avg | E24: Difference
A25: 2BD | B25: ='Current Rents'!E12 -> 1020 | C25: 1380 | E25: =B25-C25 -> -360 | F25: =IF(E25<-75,"LOOK INTO INCREASING THE RENT!","") -> LOOK INTO INCREASING THE RENT!
A26: 3BD | B26: ='Current Rents'!F12 -> 1150 | C26: 1507 | E26: =B26-C26 -> -357 | F26: =IF(E26<-75,"LOOK INTO INCREASING THE RENT!","") -> LOOK INTO INCREASING THE RENT!

Sheet 18 - Opa Locka
A2: RENT COMPARABLES ANALYSIS — OPA LOCKA 135TH ST | OPA LOCKA, FL 33054 | AD2: 18 - Opa Locka | 65 Units | LIHTC / Section 8 | 1BD, 2BD & 3BD
A3: 2860 NW 135th Street, Opa Locka, FL 33054 | Miami-Dade County
A4: Data as of June 16, 2026 | Sources: Apartments.com, HUD FMR Database, Apartment Corp Records
A5: COLUMN GUIDE — Income-restricted comps show AMI-based maximum rents (50%/60% AMI) alongside FMR. Market-rate comps show N/A for AMI columns. Actual = advertised/in-place rent. Competition Level: HIGH = direct competition; MODERATE-HIGH = partial overlap.
A6: Rank | B6: Type | C6: Property Name | E6: Address | F6: City | G6: St | H6: ZIP | I6: Distance | J6: 1BD 50% AMI | K6: 1BD 60% AMI | L6: 1BD FMR | M6: 1BD - Actual | N6: 2BD 50% AMI | O6: 2BD 60% AMI | P6: 2BD FMR | Q6: 2BD - Actual | R6: 3BD 50% AMI | S6: 3BD 60% AMI | T6: 3BD FMR | U6: 3BD - Actual | V6: Units | W6: Yr Built | X6: Yr Diff | Y6: Utils Incl. | Z6: Pet Friendly | AA6: Gated | AB6: Pool | AC6: W/D In-Unit | AD6: Competition Level | AE6: Notes / Why Competitive | AF6: Data Source
A7: ★ | B7: SUBJECT | C7: Opa Locka 135th St (SUBJECT) | E7: 2860 NW 135th Street | F7: Opa Locka | G7: FL | H7: 33054 | I7: 0.0 mi | J7: $3,872 | K7: $4,647 | L7: $1,736 | M7: ='Current Rents'!D13 -> 1470 | N7: $4,645 | O7: $5,575 | P7: $2,376 | Q7: ='Current Rents'!E13 -> 1800 | R7: $5,162 | S7: $6,195 | T7: $3,044 | U7: ='Current Rents'!F13 -> 2320 | V7: 65 | W7: 1968 | X7: 0 | Y7: Yes | Z7: No | AA7: No | AB7: No | AC7: No | AD7: SUBJECT | AE7: 65 units | LIHTC/Section 8. Year built: 1968. Subject property. | AF7: Apartment Corp Records
A8: 1 | B8: AFFORDABLE | C8: Liberty City Manor | E8: 6200 NW 7th Ave | F8: Miami | G8: FL | H8: 33150 | I8: 8.5 mi | J8: $3,872 | K8: $4,647 | L8: $1,736 | M8: Not Listed | N8: $4,645 | O8: $5,575 | P8: $2,376 | Q8: Not Listed | R8: $5,162 | S8: $6,195 | T8: $3,044 | U8: Not Listed | V8: 64 | W8: 1968 | X8: 0 | Y8: Yes | Z8: No | AA8: No | AB8: No | AC8: No | AD8: HIGH | AE8: Section 8/HUD, 1968 vintage, 64 units, 8.5 mi. Income-restricted. | AF8: HUD Multifamily Assisted Housing
A9: 2 | B9: AFFORDABLE | C9: Hialeah Gardens Apartments | E9: 1200 W 68th St | F9: Hialeah | G9: FL | H9: 33012 | I9: 5.2 mi | J9: $3,872 | K9: $4,647 | L9: $1,736 | M9: 3200 | N9: $4,645 | O9: $5,575 | P9: $2,376 | Q9: 3896 | R9: $5,162 | S9: $6,195 | T9: $3,044 | U9: 4686 | V9: 72 | W9: 1970 | X9: 2 | Y9: Yes | Z9: No | AA9: No | AB9: No | AC9: No | AD9: HIGH | AE9: Section 8/HUD, 1970 vintage, 72 units, 5.2 mi. Income-restricted. | AF9: HUD Multifamily Assisted Housing
A10: 3 | B10: AFFORDABLE | C10: Carol City Manor | E10: 18800 NW 27th Ave | F10: Miami Gardens | G10: FL | H10: 33056 | I10: 4.1 mi | J10: $3,872 | K10: $4,647 | L10: $1,736 | M10: Not Listed | N10: $4,645 | O10: $5,575 | P10: $2,376 | Q10: Not Listed | R10: $5,162 | S10: $6,195 | T10: $3,044 | U10: Not Listed | V10: 60 | W10: 1967 | X10: 1 | Y10: Yes | Z10: No | AA10: No | AB10: No | AC10: No | AD10: HIGH | AE10: Section 8/HUD, 1967 vintage, 60 units, 4.1 mi. Income-restricted. | AF10: HUD Multifamily Assisted Housing
A11: 4 | B11: AFFORDABLE | C11: North Miami HA - Arch Creek Apts | E11: 1800 NE 135th St | F11: North Miami | G11: FL | H11: 33161 | I11: 6.8 mi | J11: $3,872 | K11: $4,647 | L11: $1,736 | M11: Not Listed | N11: $4,645 | O11: $5,575 | P11: $2,376 | Q11: Not Listed | R11: $5,162 | S11: $6,195 | T11: $3,044 | U11: Not Listed | V11: 68 | W11: 1969 | X11: 1 | Y11: Yes | Z11: No | AA11: No | AB11: No | AC11: No | AD11: MODERATE-HIGH | AE11: Public Housing/HUD, 1969 vintage, 68 units, 6.8 mi. Income-restricted. | AF11: HUD Multifamily Assisted Housing
A12: 1 | B12: MARKET RATE | C12: Sherbondy Villas | D12: COMPETITION | E12: 200 S Perviz Ave | F12: Opa Locka | G12: FL | H12: 33054 | I12: 1.2 mi | J12: N/A | K12: N/A | L12: $1,736 | M12: 1400 | N12: N/A | O12: N/A | P12: $2,376 | Q12: N/A | R12: N/A | S12: N/A | T12: $3,044 | U12: N/A | V12: 32 | W12: 1967 | X12: 1 | Y12: No | Z12: No | AA12: No | AB12: No | AC12: No | AD12: HIGH | AE12: No income restrictions, 1967 vintage, 32 units, 1.2 mi. 1BD avg $1,400/mo. | AF12: apartments.com/sherbondy-villas-opa-locka-fl/
A13: 2 | B13: MARKET RATE | C13: Wellspring Apartments | E13: 14701 NW 27th Ave | F13: Opa Locka | G13: FL | H13: 33054 | I13: 1.8 mi | J13: N/A | K13: N/A | L13: $1,736 | M13: 1989 | N13: N/A | O13: N/A | P13: $2,376 | Q13: 2440 | R13: N/A | S13: N/A | T13: $3,044 | U13: N/A | V13: N/A | W13: 2024 | X13: 56 | Y13: No | Z13: Yes | AA13: No | AB13: Yes | AC13: No | AD13: HIGH | AE13: No income restrictions, 2024 vintage, 1.8 mi. 1BD avg $1,989; 2BD avg $2,440/mo. | AF13: apartments.com/wellspring-apartments-opa-locka-fl/
A14: 3 | B14: MARKET RATE | C14: Individual Units — 33054 (avg) | E14: Various, Opa Locka, FL 33054 | F14: Opa Locka | G14: FL | H14: 33054 | I14: < 3 mi | J14: N/A | K14: N/A | L14: $1,736 | M14: 1300 | N14: N/A | O14: N/A | P14: $2,376 | Q14: 1760 | R14: N/A | S14: N/A | T14: $3,044 | U14: 2598 | V14: N/A | W14: Various | X14: N/A | Y14: Varies | Z14: Varies | AA14: Varies | AB14: Varies | AC14: Varies | AD14: MODERATE-HIGH | AE14: Individual units listed on Zillow/Apartments.com in 33054 zip. Avg asking rents. | AF14: Zillow/Apartments.com — 33054 zip, Apr 2026
A15: 4 | B15: MARKET RATE | C15: Oak Enclave | E15: 2301 NW 167th St | F15: Miami Gardens | G15: FL | H15: 33056 | I15: 3.1 mi | J15: N/A | K15: N/A | L15: $1,736 | M15: 2000 | N15: N/A | O15: N/A | P15: $2,376 | Q15: 2240 | R15: N/A | S15: N/A | T15: $3,044 | U15: 2670 | V15: N/A | W15: N/A | X15: N/A | Y15: N/A | Z15: N/A | AA15: N/A | AB15: No | AC15: No | AD15: HIGH | AE15: No income restrictions, 3.1 mi. 1BD avg $2,000; 2BD avg $2,240; 3BD avg $2,670/mo. | AF15: apartments.com/oak-enclave-miami-gardens-fl/
A16: 5 | B16: MARKET RATE | C16: Emerald Bay | E16: 8570 W 40th Ave | F16: Hialeah | G16: FL | H16: 33018 | I16: 6.0 mi | J16: N/A | K16: N/A | L16: $1,736 | M16: 1900 | N16: N/A | O16: N/A | P16: $2,376 | Q16: 2200 | R16: N/A | S16: N/A | T16: $3,044 | U16: N/A | V16: N/A | W16: 2020 | X16: 52 | Y16: No | Z16: Yes | AA16: Yes | AB16: Yes | AC16: Yes | AD16: HIGH | AE16: No income restrictions, 2020 vintage, 6.0 mi. 1BD avg $1,900; 2BD avg $2,200/mo. | AF16: apartments.com/emerald-bay-hialeah-fl/
A17: 6 | B17: MARKET RATE | C17: The Oasis at Opa Locka | E17: 13400 NW 22nd Ave | F17: Opa Locka | G17: FL | H17: 33054 | I17: 2.5 mi | J17: N/A | K17: N/A | L17: $1,736 | M17: 1750 | N17: N/A | O17: N/A | P17: $2,376 | Q17: 2100 | R17: N/A | S17: N/A | T17: $3,044 | U17: 2500 | V17: N/A | W17: 2018 | X17: 50 | Y17: No | Z17: Yes | AA17: Yes | AB17: Yes | AC17: No | AD17: HIGH | AE17: No income restrictions, 2018 vintage, 2.5 mi. 1BD avg $1,750; 2BD avg $2,100; 3BD avg $2,500/mo. | AF17: apartments.com/the-oasis-at-opa-locka-fl/
A18: — | B18: BENCHMARK | C18: FY2026 FMR — Miami-Dade County | E18: N/A | F18: Opa Locka | G18: FL | H18: N/A | I18: N/A | J18: $1,736 | K18: $1,736 | L18: $1,736 | M18: N/A | N18: $2,376 | O18: $2,376 | P18: $2,376 | Q18: N/A | R18: $3,044 | S18: $3,044 | T18: $3,044 | U18: N/A | V18: N/A | W18: N/A | X18: N/A | Y18: N/A | Z18: N/A | AA18: N/A | AB18: N/A | AC18: N/A | AD18: BENCHMARK | AE18: HUD FMR for Miami-Dade County, FL, FY2026. 40th percentile rent. | AF18: HUD FMR Database (huduser.gov)
A19: — | B19: BENCHMARK | C19: Metro Market Avg — Opa Locka/Miami (Apr 2026) | E19: N/A | F19: Opa Locka | G19: FL | H19: N/A | I19: N/A | J19: $1,723 | K19: $1,723 | L19: $1,723 | M19: $1,723 | N19: $2,148 | O19: $2,148 | P19: $2,148 | Q19: $2,148 | R19: $2,589 | S19: $2,589 | T19: $2,589 | U19: $2,589 | V19: N/A | W19: N/A | X19: N/A | Y19: N/A | Z19: N/A | AA19: N/A | AB19: N/A | AC19: N/A | AD19: BENCHMARK | AE19: Live Market Average from 6 market-rate comps, Apr 30, 2026. 1BD avg $1,723; 2BD avg $2,148; 3BD avg $2,589. | AF19: Apartments.com live data, Apr 30, 2026
A21: COLOR KEY: GREEN = Subject Property | TEAL = Affordable/Income-Restricted Comp | BLUE = Market-Rate Comp | LIGHT BLUE = FMR Benchmark | YELLOW = Market Average | ORANGE = Actual Rent
A23: CURRENT RENT vs. MARKET AVERAGE
A24: Market Average = Avg of Actual Advertised Rents from 6 Market-Rate Comps (Apartments.com)
B25: Current Rents | C25: Market Avg | E25: Difference
A26: 1BD | B26: ='Current Rents'!D13 -> 1470 | C26: 1723 | E26: =B26-C26 -> -253 | F26: =IF(E26<-75,"LOOK INTO INCREASING THE RENT!","") -> LOOK INTO INCREASING THE RENT!
A27: 2BD | B27: ='Current Rents'!E13 -> 1800 | C27: 2148 | E27: =B27-C27 -> -348 | F27: =IF(E27<-75,"LOOK INTO INCREASING THE RENT!","") -> LOOK INTO INCREASING THE RENT!
A28: 3BD | B28: ='Current Rents'!F13 -> 2320 | C28: 2589 | E28: =B28-C28 -> -269 | F28: =IF(E28<-75,"LOOK INTO INCREASING THE RENT!","") -> LOOK INTO INCREASING THE RENT!

Sheet 14 - Macedonia
A2: RENT COMPARABLES ANALYSIS — MACEDONIA | PANAMA CITY, FL 32405 | Z2: 14 - Macedonia | 100 Units | LIHTC / Section 8 | 2BD & 3BD
A3: 3101 E 15th St, Panama City, FL 32405 | Bay County | Panama City MSA
A4: Data as of April 30, 2026 | Sources: Apartments.com, HUD FMR Database, Apartment Corp Records
A5: COLUMN GUIDE — Income-restricted comps show AMI-based maximum allowable rents (50%/60% AMI) alongside FMR. Market-rate comps show N/A for AMI columns. Actual = advertised/in-place rent. Competition Level: HIGH = direct competition; MODERATE-HIGH = partial overlap.
A6: Rank | B6: Type | C6: Property Name | E6: Address | F6: City | G6: St | H6: ZIP | I6: Distance | J6: 2BD 50% AMI | K6: 2BD 60% AMI | L6: 2BD FMR | M6: 2BD - Actual | N6: 3BD 50% AMI | O6: 3BD 60% AMI | P6: 3BD FMR | Q6: 3BD - Actual | R6: Units | S6: Yr Built | T6: Yr Diff | U6: Utils Incl. | V6: Pet Friendly | W6: Gated | X6: Pool | Y6: W/D In-Unit | Z6: Competition Level | AA6: Notes / Why Competitive | AB6: Data Source
A7: ★ | B7: SUBJECT | C7: Macedonia (SUBJECT) | E7: 3101 E 15th St | F7: Panama City | G7: FL | H7: 32405 | I7: 0.0 mi | J7: $3,529 | K7: $4,235 | L7: $1,426 | M7: ='Current Rents'!E14 -> 1451 | N7: $3,920 | O7: $4,705 | P7: $1,818 | Q7: ='Current Rents'!F14 -> 1613 | R7: 100 | S7: 1969 | T7: 0 | U7: Yes | V7: No | W7: No | X7: No | Y7: No | Z7: SUBJECT | AA7: 100 units | LIHTC/Section 8. Year built: 1969. Subject property. | AB7: Apartment Corp Records
A8: 1 | B8: AFFORDABLE | C8: Bay County Housing Authority | E8: 2300 E 11th St | F8: Panama City | G8: FL | H8: 32401 | I8: 3.2 mi | J8: $3,529 | K8: $4,235 | L8: $1,426 | M8: Not Listed | N8: $3,920 | O8: $4,705 | P8: $1,818 | Q8: Not Listed | R8: 100 | S8: 1969 | T8: 0 | U8: Yes | V8: No | W8: No | X8: No | Y8: No | Z8: HIGH | AA8: Public Housing/HUD, 1969 vintage, 100 units, 3.2 mi. Income-restricted. | AB8: Bay County Housing Authority
A9: 2 | B9: AFFORDABLE | C9: Pensacola HA - Attucks Court | E9: 600 N Hayne St | F9: Pensacola | G9: FL | H9: 32501 | I9: 95.0 mi | J9: $3,529 | K9: $4,235 | L9: $1,426 | M9: Not Listed | N9: $3,920 | O9: $4,705 | P9: $1,818 | Q9: Not Listed | R9: 96 | S9: 1970 | T9: 1 | U9: Yes | V9: No | W9: No | X9: No | Y9: No | Z9: LOW-MODERATE | AA9: Public Housing/HUD, 1970 vintage, 96 units, 95.0 mi. | AB9: Pensacola Housing Authority
A10: 3 | B10: AFFORDABLE | C10: Tallahassee HA - Bond Homes | E10: 1400 S Bronough St | F10: Tallahassee | G10: FL | H10: 32301 | I10: 100.0 mi | J10: $3,529 | K10: $4,235 | L10: $1,426 | M10: Not Listed | N10: $3,920 | O10: $4,705 | P10: $1,818 | Q10: Not Listed | R10: 104 | S10: 1968 | T10: 1 | U10: Yes | V10: No | W10: No | X10: No | Y10: No | Z10: LOW-MODERATE | AA10: Public Housing/HUD, 1968 vintage, 104 units, 100.0 mi. | AB10: Tallahassee Housing Authority
A11: 4 | B11: AFFORDABLE | C11: Panama City Beach Housing Authority | E11: 800 Thomas Dr | F11: Panama City Beach | G11: FL | H11: 32408 | I11: 8.5 mi | J11: $3,529 | K11: $4,235 | L11: $1,426 | M11: Not Listed | N11: $3,920 | O11: $4,705 | P11: $1,818 | Q11: Not Listed | R11: 88 | S11: 1970 | T11: 1 | U11: Yes | V11: No | W11: No | X11: No | Y11: No | Z11: HIGH | AA11: Section 8/HUD, 1970 vintage, 88 units, 8.5 mi. | AB11: HUD Multifamily Assisted Housing
A12: 1 | B12: MARKET RATE | C12: Arbor Crossing at Mill Bayou | D12: COMPETITION | E12: 198 Mill Bayou Blvd | F12: Panama City | G12: FL | H12: 32404 | I12: 3.2 mi | J12: N/A | K12: N/A | L12: $1,426 | M12: 1559 | N12: N/A | O12: N/A | P12: $1,818 | Q12: 1799 | R12: N/A | S12: 2024 | T12: 55 | U12: No | V12: Yes | W12: Yes | X12: Yes | Y12: Yes | Z12: HIGH | AA12: No income restrictions, 2024 vintage, 3.2 mi. 2BD $1,559 / 3BD $1,799. | AB12: apartments.com/arbor-crossing-at-mill-bayou-panama-city-fl/
A13: 2 | B13: MARKET RATE | C13: The Kelly at 23rd Luxury Apts | E13: 2002 Wilson Ave | F13: Panama City | G13: FL | H13: 32405 | I13: 0.5 mi | J13: N/A | K13: N/A | L13: $1,426 | M13: 1839 | N13: N/A | O13: N/A | P13: $1,818 | Q13: 1850 | R13: N/A | S13: 2025 | T13: 56 | U13: No | V13: Yes | W13: Yes | X13: Yes | Y13: Yes | Z13: HIGH | AA13: No income restrictions, 2025 vintage, 0.5 mi. 2BD $1,839 / 3BD $1,850. | AB13: apartments.com/the-kelly-at-23rd-panama-city-fl/
A14: 3 | B14: MARKET RATE | C14: Residences at SweetBay | E14: 3100 Sweetbay Ave | F14: Panama City | G14: FL | H14: 32405 | I14: 1.1 mi | J14: N/A | K14: N/A | L14: $1,426 | M14: 1558 | N14: N/A | O14: N/A | P14: $1,818 | Q14: 2015 | R14: N/A | S14: 2022 | T14: 53 | U14: No | V14: Yes | W14: Yes | X14: Yes | Y14: Yes | Z14: HIGH | AA14: No income restrictions, 2022 vintage, 1.1 mi. 2BD $1,558 / 3BD $2,015. | AB14: apartments.com/residences-at-sweetbay-panama-city-fl/
A15: 4 | B15: MARKET RATE | C15: Exchange at North Bay | E15: 3625 Frankford Ave | F15: Panama City | G15: FL | H15: 32405 | I15: 0.8 mi | J15: N/A | K15: N/A | L15: $1,426 | M15: 1529 | N15: N/A | O15: N/A | P15: $1,818 | Q15: 1786 | R15: N/A | S15: 2022 | T15: 53 | U15: No | V15: Yes | W15: Yes | X15: Yes | Y15: Yes | Z15: HIGH | AA15: No income restrictions, 2022 vintage, 0.8 mi. 2BD $1,529 / 3BD $1,786. | AB15: apartments.com/exchange-at-north-bay-panama-city-fl/
A16: 5 | B16: MARKET RATE | C16: Eagles Landing Luxury Apts | E16: 2870 Harrison Ave | F16: Panama City | G16: FL | H16: 32405 | I16: 1.5 mi | J16: N/A | K16: N/A | L16: $1,426 | M16: 1509 | N16: N/A | O16: N/A | P16: $1,818 | Q16: 1770 | R16: N/A | S16: 1993 | T16: 24 | U16: No | V16: Yes | W16: No | X16: Yes | Y16: No | Z16: HIGH | AA16: No income restrictions, 1993 vintage, 1.5 mi. 2BD $1,509 / 3BD $1,770. | AB16: apartments.com/eagles-landing-luxury-apts-panama-city-fl/
A17: 6 | B17: MARKET RATE | C17: The Enclave | E17: 2950 Harrison Ave | F17: Panama City | G17: FL | H17: 32405 | I17: 1.4 mi | J17: N/A | K17: N/A | L17: $1,426 | M17: 1525 | N17: N/A | O17: N/A | P17: $1,818 | Q17: 1700 | R17: N/A | S17: 1993 | T17: 24 | U17: No | V17: Yes | W17: No | X17: Yes | Y17: No | Z17: HIGH | AA17: No income restrictions, 1993 vintage, 1.4 mi. 2BD $1,525 / 3BD $1,700. | AB17: apartments.com/the-enclave-panama-city-fl/
A18: — | B18: BENCHMARK | C18: FY2026 FMR — Bay County, FL | E18: N/A | F18: Panama City | G18: FL | H18: N/A | I18: N/A | J18: $1,426 | K18: $1,426 | L18: $1,426 | M18: N/A | N18: $1,818 | O18: $1,818 | P18: $1,818 | Q18: N/A | R18: N/A | S18: N/A | T18: N/A | U18: N/A | V18: N/A | W18: N/A | X18: N/A | Y18: N/A | Z18: BENCHMARK | AA18: HUD FMR for Bay County (Panama City MSA), FL, FY2026. 40th percentile rent. | AB18: HUD FMR Database (huduser.gov)
A19: — | B19: BENCHMARK | C19: Metro Market Avg — Panama City (Apr 2026) | E19: N/A | F19: Panama City | G19: FL | H19: N/A | I19: N/A | J19: $1,586 | K19: $1,586 | L19: $1,586 | M19: $1,586 | N19: $1,820 | O19: $1,820 | P19: $1,820 | Q19: $1,820 | R19: N/A | S19: N/A | T19: N/A | U19: N/A | V19: N/A | W19: N/A | X19: N/A | Y19: N/A | Z19: BENCHMARK | AA19: Live Market Average from 6 comps, Apr 30, 2026. 2BD avg $1,586 / 3BD avg $1,820. | AB19: Apartments.com live data, Apr 30, 2026
A21: COLOR KEY: GREEN = Subject Property | TEAL = Affordable/Income-Restricted Comp | BLUE = Market-Rate Comp | LIGHT BLUE = FMR Benchmark | YELLOW = Market Average | ORANGE = Actual Rent
A23: CURRENT RENT vs. MARKET AVERAGE
A24: Market Average = Avg of Actual Advertised Rents from 6 Market-Rate Comps (Apartments.com)
B25: Current Rents | C25: Market Avg | E25: Difference
A26: 2BD | B26: ='Current Rents'!E14 -> 1451 | C26: 1586 | E26: =B26-C26 -> -135 | F26: =IF(E26<-75,"LOOK INTO INCREASING THE RENT!","") -> LOOK INTO INCREASING THE RENT!
A27: 3BD | B27: ='Current Rents'!F14 -> 1613 | C27: 1820 | E27: =B27-C27 -> -207 | F27: =IF(E27<-75,"LOOK INTO INCREASING THE RENT!","") -> LOOK INTO INCREASING THE RENT!

Sheet 48 - Coral Village
A8: RENT COMPARABLES ANALYSIS — CORAL VILLAGE | CAPE CORAL, FL 33990 | Z8: 48 - Coral Village | 72 Units | Section 8 / HUD | 1BD & 2BD
A9: Cape Coral, FL 33990 | Lee County | Cape Coral-Fort Myers MSA
A10: Data as of April 30, 2026 | Sources: Apartments.com, HUD FMR Database, Apartment Corp Records
A11: COLUMN GUIDE — Income-restricted comps show AMI-based maximum allowable rents (50%/60% AMI) alongside FMR. Market-rate comps show N/A for AMI columns. Actual = advertised/in-place rent. Competition Level: HIGH = direct competition; MODERATE-HIGH = partial overlap.
A12: Rank | B12: Type | C12: Property Name | E12: Address | F12: City | G12: St | H12: ZIP | I12: Distance | J12: 1BD 50% AMI | K12: 1BD 60% AMI | L12: 1BD FMR | M12: 1BD - Actual | N12: 2BD 50% AMI | O12: 2BD 60% AMI | P12: 2BD FMR | Q12: 2BD - Actual | R12: Units | S12: Yr Built | T12: Yr Diff | U12: Utils Incl. | V12: Pet Friendly | W12: Gated | X12: Pool | Y12: W/D In-Unit | Z12: Competition Level | AA12: Notes / Why Competitive | AB12: Data Source
A13: ★ | B13: SUBJECT | C13: Coral Village (SUBJECT) | E13: Cape Coral | F13: Cape Coral | G13: FL | H13: 33990 | I13: 0.0 mi | J13: $3,193 | K13: $3,832 | L13: $1,371 | M13: ='Current Rents'!D15 -> 1375 | N13: $3,829 | O13: $4,595 | P13: $1,876 | Q13: ='Current Rents'!E15 -> 1552 | R13: 72 | S13: 1999 | T13: 0 | U13: Yes | V13: No | W13: No | X13: Yes | Y13: No | Z13: SUBJECT | AA13: 72 units | Section 8/HUD. Year built: 1999. Subject property. | AB13: Apartment Corp Records
A14: 1 | B14: AFFORDABLE | C14: Brittany II | E14: 4050 Winkler Ave Ext | F14: Fort Myers | G14: FL | H14: 33916 | I14: 8.0 mi | J14: $3,193 | K14: $3,832 | L14: $1,371 | M14: Not Listed | N14: $3,829 | O14: $4,595 | P14: $1,876 | Q14: Not Listed | R14: 112 | S14: 2000 | T14: 1 | U14: Yes | V14: No | W14: No | X14: No | Y14: No | Z14: HIGH | AA14: LIHTC, 2000 vintage, 112 units, 8.0 mi. Income-restricted. | AB14: HUD LIHTC Database
A15: 2 | B15: AFFORDABLE | C15: Brittany | E15: 4054 Winkler Ave | F15: Fort Myers | G15: FL | H15: 33916 | I15: 7.9 mi | J15: $3,193 | K15: $3,832 | L15: $1,371 | M15: Not Listed | N15: $3,829 | O15: $4,595 | P15: $1,876 | Q15: Not Listed | R15: 208 | S15: 1999 | T15: 0 | U15: Yes | V15: No | W15: No | X15: No | Y15: No | Z15: HIGH | AA15: LIHTC, 1999 vintage, 208 units, 7.9 mi. Income-restricted. | AB15: HUD LIHTC Database
A16: 3 | B16: AFFORDABLE | C16: Crossings at Cape Coral | E16: 1150 Hancock Crk Blvd | F16: Cape Coral | G16: FL | H16: 33909 | I16: 7.7 mi | J16: $3,193 | K16: $3,832 | L16: $1,371 | M16: Not Listed | N16: $3,829 | O16: $4,595 | P16: $1,876 | Q16: 1224 | R16: 168 | S16: 2000 | T16: 1 | U16: Yes | V16: No | W16: No | X16: No | Y16: No | Z16: HIGH | AA16: LIHTC, 2000 vintage, 168 units, 7.7 mi. Income-restricted. | AB16: HUD LIHTC Database
A17: 4 | B17: AFFORDABLE | C17: Westchase | E17: 3810 Metro Pkwy | F17: Fort Myers | G17: FL | H17: 33916 | I17: 6.8 mi | J17: $3,193 | K17: $3,832 | L17: $1,371 | M17: Not Listed | N17: $3,829 | O17: $4,595 | P17: $1,876 | Q17: Not Listed | R17: 352 | S17: 1999 | T17: 0 | U17: Yes | V17: No | W17: No | X17: No | Y17: No | Z17: HIGH | AA17: LIHTC, 1999 vintage, 352 units, 6.8 mi. Income-restricted. | AB17: HUD LIHTC Database
A18: 1 | B18: MARKET RATE | C18: Cape at Savona Point | D18: COMPETITION | E18: 1730 Savona Point Cir | F18: Cape Coral | G18: FL | H18: 33914 | I18: 5.2 mi | J18: N/A | K18: N/A | L18: $1,371 | M18: 1287 | N18: N/A | O18: N/A | P18: $1,876 | Q18: 1472 | R18: N/A | S18: 2021 | T18: 22 | U18: No | V18: Yes | W18: Yes | X18: Yes | Y18: Yes | Z18: HIGH | AA18: No income restrictions, 2021 vintage, 5.2 mi. 1BD $1,287 / 2BD $1,472. | AB18: apartments.com/cape-at-savona-point-cape-coral-fl/
A19: 2 | B19: MARKET RATE | C19: The Palms at Cape Coral | E19: 701 SW Pine Island Rd | F19: Cape Coral | G19: FL | H19: 33991 | I19: 4.8 mi | J19: N/A | K19: N/A | L19: $1,371 | M19: 1243 | N19: N/A | O19: N/A | P19: $1,876 | Q19: 1503 | R19: N/A | S19: 2023 | T19: 24 | U19: No | V19: Yes | W19: Yes | X19: Yes | Y19: Yes | Z19: HIGH | AA19: No income restrictions, 2023 vintage, 4.8 mi. 1BD $1,243 / 2BD $1,503. | AB19: apartments.com/the-palms-at-cape-coral-fl/
A20: 3 | B20: MARKET RATE | C20: Oasis at Surfside | E20: 2200 Oasis Palm Cir | F20: Cape Coral | G20: FL | H20: 33991 | I20: 4.1 mi | J20: N/A | K20: N/A | L20: $1,371 | M20: 1389 | N20: N/A | O20: N/A | P20: $1,876 | Q20: 1549 | R20: N/A | S20: 2022 | T20: 23 | U20: No | V20: Yes | W20: Yes | X20: Yes | Y20: Yes | Z20: HIGH | AA20: No income restrictions, 2022 vintage, 4.1 mi. 1BD $1,389 / 2BD $1,549. | AB20: apartments.com/oasis-at-surfside-cape-coral-fl/
A21: 4 | B21: MARKET RATE | C21: Springs at Coral Shores | E21: 606 SW 29th Ave | F21: Cape Coral | G21: FL | H21: 33991 | I21: 3.9 mi | J21: N/A | K21: N/A | L21: $1,371 | M21: 1327 | N21: N/A | O21: N/A | P21: $1,876 | Q21: 1480 | R21: N/A | S21: 2020 | T21: 21 | U21: No | V21: Yes | W21: Yes | X21: Yes | Y21: Yes | Z21: HIGH | AA21: No income restrictions, 2020 vintage, 3.9 mi. 1BD $1,327 / 2BD $1,480. | AB21: apartments.com/springs-at-coral-shores-cape-coral-fl/
A22: 5 | B22: MARKET RATE | C22: Coralina Apartments | E22: 3305 Grant Cove Cir | F22: Cape Coral | G22: FL | H22: 33991 | I22: 4.5 mi | J22: N/A | K22: N/A | L22: $1,371 | M22: 1360 | N22: N/A | O22: N/A | P22: $1,876 | Q22: 1694 | R22: N/A | S22: 2022 | T22: 23 | U22: No | V22: Yes | W22: Yes | X22: Yes | Y22: Yes | Z22: HIGH | AA22: No income restrictions, 2022 vintage, 4.5 mi. 1BD $1,360 / 2BD $1,694. | AB22: apartments.com/coralina-apartments-cape-coral-fl/
A23: 6 | B23: MARKET RATE | C23: Apts at Isles of Porto Vista | E23: 3936 Pomodoro Cir | F23: Cape Coral | G23: FL | H23: 33909 | I23: 7.3 mi | J23: N/A | K23: N/A | L23: $1,371 | M23: 1424 | N23: N/A | O23: N/A | P23: $1,876 | Q23: 1499 | R23: N/A | S23: 2023 | T23: 24 | U23: No | V23: Yes | W23: Yes | X23: Yes | Y23: Yes | Z23: HIGH | AA23: No income restrictions, 2023 vintage, 7.3 mi. 1BD $1,424 / 2BD $1,499. | AB23: apartments.com/isles-of-porto-vista-cape-coral-fl/
A24: — | B24: BENCHMARK | C24: FY2026 FMR — Cape Coral-Fort Myers MSA | E24: N/A | F24: Cape Coral | G24: FL | H24: N/A | I24: N/A | J24: $1,371 | K24: $1,371 | L24: $1,371 | M24: N/A | N24: $1,876 | O24: $1,876 | P24: $1,876 | Q24: N/A | R24: N/A | S24: N/A | T24: N/A | U24: N/A | V24: N/A | W24: N/A | X24: N/A | Y24: N/A | Z24: BENCHMARK | AA24: HUD FMR for Cape Coral-Fort Myers MSA, FY2026. 40th percentile rent. | AB24: HUD FMR Database (huduser.gov)
A25: — | B25: BENCHMARK | C25: Metro Market Avg — Cape Coral (Apr 2026) | E25: N/A | F25: Cape Coral | G25: FL | H25: N/A | I25: N/A | J25: $1,338 | K25: $1,338 | L25: $1,338 | M25: $1,338 | N25: $1,533 | O25: $1,533 | P25: $1,533 | Q25: $1,533 | R25: N/A | S25: N/A | T25: N/A | U25: N/A | V25: N/A | W25: N/A | X25: N/A | Y25: N/A | Z25: BENCHMARK | AA25: Live Market Average from 6 comps, Apr 30, 2026. 1BD avg $1,338 / 2BD avg $1,533. | AB25: Apartments.com live data, Apr 30, 2026
A27: COLOR KEY: GREEN = Subject Property | TEAL = Affordable/Income-Restricted Comp | BLUE = Market-Rate Comp | LIGHT BLUE = FMR Benchmark | YELLOW = Market Average | ORANGE = Actual Rent
A29: CURRENT RENT vs. MARKET AVERAGE
A30: Market Average = Avg of Actual Advertised Rents from 6 Market-Rate Comps (Apartments.com)
B31: Current Rents | C31: Market Avg | E31: Difference
A32: 1BD | B32: ='Current Rents'!D15 -> 1375 | C32: 1338 | E32: =B32-C32 -> 37 | F32: =IF(E32<-75,"LOOK INTO INCREASING THE RENT!","")
A33: 2BD | B33: ='Current Rents'!E15 -> 1552 | C33: 1533 | E33: =B33-C33 -> 19 | F33: =IF(E33<-75,"LOOK INTO INCREASING THE RENT!","")

Sheet 15 - Holiday
A8: RENT COMPARABLES ANALYSIS — HOLIDAY APTS | NATCHEZ, MS 39120 | AG8: 15 - Holiday | 115 Units | Section 8 / HUD | 2BD, 3BD, 4BD & 5BD
A9: 601 Old Washington Road, Natchez, MS 39120 | Adams County | FY2026 HUD FMR Area: Adams County, MS
A10: Data as of April 30, 2026 | Sources: Apartments.com, HUD FMR Database, Apartment Corp Records
A11: COLUMN GUIDE — Income-restricted comps show AMI-based maximum allowable rents (50%/60% AMI) alongside FMR. Market-rate comps show N/A for AMI columns. Actual = advertised/in-place rent. Competition Level: HIGH = direct competition; MODERATE-HIGH = partial overlap.
A12: Rank | B12: Type | C12: Property Name | E12: Address | F12: City | G12: St | H12: ZIP | I12: Distance | J12: 2BD 50% AMI | K12: 2BD 60% AMI | L12: 2BD FMR | M12: 2BD - Actual | N12: 3BD 50% AMI | O12: 3BD 60% AMI | P12: 3BD FMR | Q12: 3BD - Actual | R12: 4BD 50% AMI | S12: 4BD 60% AMI | T12: 4BD FMR | U12: 4BD - Actual | V12: 5BD 50% AMI | W12: 5BD 60% AMI | X12: 5BD FMR | Y12: Units | Z12: Yr Built | AA12: Yr Diff | AB12: Utils Incl. | AC12: Pet Friendly | AD12: Gated | AE12: Pool | AF12: W/D In-Unit | AG12: Competition Level | AH12: Notes / Why Competitive | AI12: Data Source
A13: ★ | B13: SUBJECT | C13: Holiday Apts (SUBJECT) | E13: 601 Old Washington Road | F13: Natchez | G13: MS | H13: 39120 | I13: 0.0 mi | J13: $2,591 | K13: $3,110 | L13: $820 | M13: ='Current Rents'!E16 -> 935 | N13: $2,879 | O13: $3,455 | P13: $1,040 | Q13: ='Current Rents'!F16 -> 1073 | R13: $3,112 | S13: $3,735 | T13: $1,202 | U13: ='Current Rents'!G16 -> 1147 | V13: $3,341 | W13: $4,010 | X13: $1,382 | Y13: 115 | Z13: 1951 | AA13: 0 | AB13: Yes | AC13: No | AD13: No | AE13: No | AF13: No | AG13: SUBJECT | AH13: 115 units | Section 8/HUD. Year built: 1951. Subject property. | AI13: Apartment Corp Records
